Workbook
Name Calc_Actif: P_General!$E$4
Name Calc_Arret: Calculateurs!$C$125:$C$127
Name Calc_Auth: Calculateurs!$D$8:$D$31
Name Calc_Concours: Calculateurs!$A$105:$E$114
Name Calc_Cout: Calculateurs!$C$187:$C$188
Name Calc_Desist: Calculateurs!$C$183:$C$184
Name Calc_Equip: Calculateurs!$A$164:$H$171
Name Calc_EquipParam: Calculateurs!$C$158:$C$161
Name Calc_Lots: Calculateurs!$A$42:$D$81
Name Calc_Mainlevee: Calculateurs!$C$90:$C$92
Name Calc_Mixte: Calculateurs!$C$178:$C$180
Name Calc_Plan: Calculateurs!$A$140:$D$151
Name Calc_PlanDate: Calculateurs!$C$138
Name Calc_Tirage: Calculateurs!$C$132:$C$134
Name Calc_Valeur: Calculateurs!$C$39
Name In_Calc: Saisie!$F$13:$F$92
Name In_Cles: Saisie!$B$13:$B$92
Name In_Etat: Saisie!$I$13:$I$92
Name In_Retenue: Saisie!$G$13:$G$92
Name In_Saisie: Saisie!$E$13:$E$92
Name P_Classes: P_General!$A$27:$E$36
Name P_ClsCodes: P_General!$A$27:$A$36
Name P_Date: P_General!$B$5
Name P_DecTbl: P_General!$A$52:$B$56
Name P_DomCodes: P_General!$A$16:$A$23
Name P_DomNoms: P_General!$B$16:$B$23
Name P_DomPoids: P_General!$C$16:$C$23
Name P_DPD1: P_General!$B$45
Name P_DPD2: P_General!$B$46
Name P_DPD3: P_General!$B$47
Name P_ExtraKey: P_General!$B$12
Name P_GO: P_General!$B$7
Name P_GWC: P_General!$B$8
Name P_PDa: P_General!$B$10
Name P_PDb: P_General!$B$11
Name P_PhaseCodes: P_General!$A$40:$A$42
Name P_PhaseHdr: P_General!$B$39:$I$39
Name P_PhaseTbl: P_General!$A$40:$I$42
Name P_Scale: P_General!$B$6
Name P_SegCodes: P_Ajustements!$A$5:$A$24
Name P_SegLabels: P_Ajustements!$B$5:$B$11
Name P_SegLabelsAll: P_Ajustements!$B$5:$B$24
Name P_SegTbl: P_Ajustements!$A$5:$C$24
Name P_Version: P_General!$B$4
Name P_WATCH: P_General!$B$9
Name P_ZoneCodes: P_Ajustements!$E$5:$E$24
Name P_ZoneLabels: P_Ajustements!$F$5:$F$13
Name P_ZoneLabelsAll: P_Ajustements!$F$5:$F$24
Name P_ZoneTbl: P_Ajustements!$E$5:$G$24
Name R_AuthCodes: P_Referentiels!$A$6:$A$29
Name R_AuthTbl: P_Referentiels!$A$6:$I$29
Name R_FinCodes: P_Referentiels!$A$34:$A$45
Name R_FinTbl: P_Referentiels!$A$34:$C$45
Name R_ModCode: P_Referentiels!$B$66:$B$75
Name R_ModKey: P_Referentiels!$A$66:$A$75
Name R_ModLab: P_Referentiels!$C$66:$C$75
Name Res_Adj: Resultat!$C$11
Name Res_Alertes: Resultat!$C$26
Name Res_AlertesLib: Resultat!$P$137
Name Res_ClasseInt: Resultat!$C$8

Sheet Accueil
B1: Outil de scoring — Promotion immobilière
B2: ="Modèle PI_PROMOTION "&P_Version&" (publié le "&P_Date&") · outil 5.1 du 05/10/2026" -> Modèle PI_PROMOTION v5.0.0 (publié le 2026-10-01) · outil 5.1 du 05/10/2026
B4: Dossier en cours
B5: Référence · projet | C5: =IF(Saisie!C4="","(aucun dossier — commencez par l'onglet Saisie)",Saisie!C4&" — "&Saisie!C5) -> EXEMPLE — Dossier d'exemple — à remplacer (ruban « Scoring PI » › Nouveau dossier)
B6: Score final / 100 | C6: =Res_ScoreFinal -> 68.46
B7: Décision | C7: =IFERROR(VLOOKUP(Res_Decision,P_DecTbl,2,FALSE),Res_Decision) -> Favorable sous conditions
B8: Classe interne | C8: =Res_ClasseInt -> Surveillance
B9: Critères renseignés | C9: =Saisie!I7 -> 37 / 37
B10: Données décisionnelles manquantes | C10: =Saisie!I8 -> 0
C11: → Ouvrir la fiche de résultat
B13: Comment faire
B14: 1. Nouveau dossier | C14: Ruban « Scoring PI » › Nouveau dossier : vide la saisie et les calculateurs. Sans macros : effacez les cellules jaunes de l'onglet Saisie.
B15: 2. Renseigner la saisie | C15: Identité du dossier puis données, dans les cellules jaunes (listes en clair). Laissez vide une donnée inconnue. La colonne « État » signale ce qui manque ; le résultat se met à jour en direct en haut de la feuille.
B16: 3. Calculateurs (facultatif) | C16: Autorisations, ventes sécurisées, mainlevée, division des risques, arrêt de chantier, déblocages, équipements exigés, programme mixte : ils calculent 16 données de la saisie (votre saisie directe prime).
B17: 4. Lire et imprimer la fiche | C17: Décision, notes, données manquantes, conditions à lever, alertes, points d'attention. Imprimable sur une page (Ctrl+P) ; ruban › Exporter la fiche en PDF.
B18: 5. Enregistrer le dossier | C18: Ruban › Enregistrer le dossier : il est rangé dans l'onglet Portefeuille (même référence = mise à jour). Ruban › Ouvrir un dossier pour le recharger.
B19: 6. Aller plus loin | C19: Stress test (7 scénarios), scoring de tout le portefeuille, journal des calculs (onglet Historique), aide détaillée (onglet Aide).
B21: Macros et ruban « Scoring PI »
B22: Fichier .xlsm | C22: Les macros et l'onglet de ruban « Scoring PI » sont intégrés : rien à installer. Si Excel indique que les macros sont bloquées (fichier reçu par e-mail ou téléchargé) : fermez le fichier, clic droit › Propriétés › cochez « Débloquer » › OK, rouvrez-le puis cliquez « Activer le contenu ».
B23: Sans macros | C23: Le calcul (saisie, fiche, résultat) fonctionne sans macros, y compris dans le fichier .xlsx : seules les actions du ruban (nouveau dossier, enregistrer, PDF, stress, portefeuille) sont indisponibles.
B25: Bon à savoir
B26: Vide ≠ 0 | C26: Une donnée vide est « absente » : note plancher, ou « dossier incomplet » si elle est décisionnelle. Ne saisissez jamais 0 ou « Non » à la place d'une donnée inconnue.
B27: Pourcentages | C27: Saisir les pourcentages en points : 62 pour 62 %. Une valeur comme 0,62 est signalée dans la colonne « État ».
B28: Feuilles protégées | C28: Seules les cellules jaunes sont modifiables (protection sans mot de passe : Révision › Ôter la protection si besoin).
B29: Paramètres du modèle | C29: Onglets P_* masqués : ruban › Paramètres (afficher / masquer). Toute modification : Valider le modèle, puis informer le propriétaire du modèle.
B30: Décision officielle | C30: Ce classeur est un outil d'aide (simulation, préparation de comité, formation). La décision officielle se prend dans l'application.

Sheet Saisie
A1: Saisie du dossier
A2: Renseignez les cellules jaunes (listes déroulantes en clair). Laissez VIDE une donnée inconnue : elle n'améliore jamais le résultat. La colonne « État » signale ce qui manque.
H3: Résultat en direct
A4: Référence dossier | C4: EXEMPLE | H4: Score final (0–100) | I4: =Res_ScoreFinal -> 68.46
A5: Nom du projet | C5: Dossier d'exemple — à remplacer (ruban « Scoring PI » › Nouveau dossier) | H5: Décision | I5: =IFERROR(VLOOKUP(Res_Decision,P_DecTbl,2,FALSE),Res_Decision) -> Favorable sous conditions
A6: Segment | C6: Moyen-haut standing | D6: =IF(C6="","",IFERROR(INDEX(P_SegCodes,MATCH(C6,P_SegLabelsAll,0)),C6)) -> moyen_haut | H6: Classe interne | I6: =Res_ClasseInt -> Surveillance
A7: Zone | C7: Casablanca — centre | D7: =IF(C7="","",IFERROR(INDEX(P_ZoneCodes,MATCH(C7,P_ZoneLabelsAll,0)),C7)) -> casa_centre | H7: Critères renseignés | I7: =SUMPRODUCT((G13:G49<>"")*1)&" / 37" -> 37 / 37
A8: Classe réglementaire BAM | C8: SAIN | E8: =IFERROR(IF(NOT(ISNUMBER(INDEX(In_Retenue,MATCH("dpd_days",In_Cles,0)))),"",IF(INDEX(In_Retenue,MATCH("dpd_days",In_Cles,0))>=P_DPD3,"COMPROMIS",IF(INDEX(In_Retenue,MATCH("dpd_days",In_Cles,0))>=P_DPD2,"DOUTEUX",IF(INDEX(In_Retenue,MATCH("dpd_days",In_Cles,0))>=P_DPD1,"PRE_DOUTEUX","SAIN")))),"") -> SAIN | F8: =IF(OR(C8="",E8=""),"",IF(MATCH(C8,P_ClsCodes,0)<MATCH(E8,P_ClsCodes,0),"⚠ Moins sévère que le retard","Cohérente avec le retard")) -> Cohérente avec le retard | H8: Données décisionnelles manquantes | I8: =COUNTIF(I13:I92,"⚠ Manquant*") -> 0
A9: Phase du projet (challenger) | C9: CONSTRUCTION | H9: Valeurs à vérifier (%) | I9: =COUNTIF(I13:I92,"⚠ En %*")+COUNTIF(I13:I92,"⚠ Valeur hors*") -> 0
A10: Version du modèle | C10: =P_Version&" — "&P_Date -> v5.0.0 — 2026-10-01 | H10: → Ouvrir la fiche de résultat | I10: =IF(Calc_Actif,"","⚠ Calculateurs désactivés")
A12: Section | B12: Clé technique | C12: Donnée | D12: Type | E12: Votre saisie | F12: Calculé (Calculateurs) | G12: Valeur utilisée | H12: Unité / aide | I12: État
A13: D1 — Sponsor & Gouvernance | B13: promoter_completed_projects | C13: Projets similaires livrés (5 ans) | D13: NUM | E13: 8 | G13: =IF(E13<>"",E13,IF(F13="","",F13)) -> 8 | H13: nombre de projets (ex. 8) | I13: =IF(FALSE*ISNUMBER(G13)*(N(G13)>0)*(N(G13)<1),"⚠ En % : saisir 62 pour 62 %",IF(G13<>"","✔ Renseigné",IF(OR(COUNTIFS(P_Criteres!$F$5:$F$64,B13,P_Criteres!$G$5:$G$64,"Oui")>0,COUNTIFS(P_Criteres!$F$5:$F$64,B13,P_Criteres!$K$5:$K$64,"Oui")>0,B13=P_ExtraKey),"⚠ Manquant — décisionnel","○ Non renseigné"))) -> ✔ Renseigné
A14: D1 — Sponsor & Gouvernance | B14: promoter_gearing | C14: Gearing promoteur (dettes nettes / FP) | D14: NUM | E14: 85 | G14: =IF(E14<>"",E14,IF(F14="","",F14)) -> 85 | H14: % (dettes / fonds propres, ex. 85) | I14: =IF(TRUE*ISNUMBER(G14)*(N(G14)>0)*(N(G14)<1),"⚠ En % : saisir 62 pour 62 %",IF(G14<>"","✔ Renseigné",IF(OR(COUNTIFS(P_Criteres!$F$5:$F$64,B14,P_Criteres!$G$5:$G$64,"Oui")>0,COUNTIFS(P_Criteres!$F$5:$F$64,B14,P_Criteres!$K$5:$K$64,"Oui")>0,B14=P_ExtraKey),"⚠ Manquant — décisionnel","○ Non renseigné"))) -> ✔ Renseigné
A15: D1 — Sponsor & Gouvernance | B15: governance_quality | C15: Gouvernance & structure juridique | D15: QUAL | E15: Claire / structurée | G15: =IF(E15<>"",IF(SUMPRODUCT((P_Baremes!$A$5:$A$400="D1C3")*(P_Baremes!$F$5:$F$400=E15))>0,INDEX(P_Baremes!$C$5:$C$400,SUMPRODUCT(MAX((P_Baremes!$A$5:$A$400="D1C3")*(P_Baremes!$F$5:$F$400=E15)*(ROW(P_Baremes!$A$5:$A$400)-4)))),E15),IF(F15="","",F15)) -> claire | H15: choisir dans la liste | I15: =IF(FALSE*ISNUMBER(G15)*(N(G15)>0)*(N(G15)<1),"⚠ En % : saisir 62 pour 62 %",IF(AND(E15<>"",COUNTIFS(P_Baremes!$A$5:$A$400,"D1C3",P_Baremes!$C$5:$C$400,G15)=0),"⚠ Valeur hors liste",IF(G15<>"","✔ Renseigné",IF(OR(COUNTIFS(P_Criteres!$F$5:$F$64,B15,P_Criteres!$G$5:$G$64,"Oui")>0,COUNTIFS(P_Criteres!$F$5:$F$64,B15,P_Criteres!$K$5:$K$64,"Oui")>0,B15=P_ExtraKey),"⚠ Manquant — décisionnel","○ Non renseigné")))) -> ✔ Renseigné
A16: D1 — Sponsor & Gouvernance | B16: mono_project_concentration | C16: Concentration mono-projet (CA projet / CA total) | D16: NUM | E16: 35 | G16: =IF(E16<>"",E16,IF(F16="","",F16)) -> 35 | H16: % (ex. 35) | I16: =IF(TRUE*ISNUMBER(G16)*(N(G16)>0)*(N(G16)<1),"⚠ En % : saisir 62 pour 62 %",IF(G16<>"","✔ Renseigné",IF(OR(COUNTIFS(P_Criteres!$F$5:$F$64,B16,P_Criteres!$G$5:$G$64,"Oui")>0,COUNTIFS(P_Criteres!$F$5:$F$64,B16,P_Criteres!$K$5:$K$64,"Oui")>0,B16=P_ExtraKey),"⚠ Manquant — décisionnel","○ Non renseigné"))) -> ✔ Renseigné
A17: D1 — Sponsor & Gouvernance | B17: promoter_type | C17: Typologie promoteur | D17: QUAL | E17: Structuré | G17: =IF(E17<>"",IF(SUMPRODUCT((P_Baremes!$A$5:$A$400="D1C5")*(P_Baremes!$F$5:$F$400=E17))>0,INDEX(P_Baremes!$C$5:$C$400,SUMPRODUCT(MAX((P_Baremes!$A$5:$A$400="D1C5")*(P_Baremes!$F$5:$F$400=E17)*(ROW(P_Baremes!$A$5:$A$400)-4)))),E17),IF(F17="","",F17)) -> structure | H17: choisir dans la liste | I17: =IF(FALSE*ISNUMBER(G17)*(N(G17)>0)*(N(G17)<1),"⚠ En % : saisir 62 pour 62 %",IF(AND(E17<>"",COUNTIFS(P_Baremes!$A$5:$A$400,"D1C5",P_Baremes!$C$5:$C$400,G17)=0),"⚠ Valeur hors liste",IF(G17<>"","✔ Renseigné",IF(OR(COUNTIFS(P_Criteres!$F$5:$F$64,B17,P_Criteres!$G$5:$G$64,"Oui")>0,COUNTIFS(P_Criteres!$F$5:$F$64,B17,P_Criteres!$K$5:$K$64,"Oui")>0,B17=P_ExtraKey),"⚠ Manquant — décisionnel","○ Non renseigné")))) -> ✔ Renseigné
A18: D1 — Sponsor & Gouvernance | B18: equity_injected_ratio | C18: Apport effectif (injecté / prévu) | D18: NUM | E18: 100 | G18: =IF(E18<>"",E18,IF(F18="","",F18)) -> 100 | H18: % (ex. 100) | I18: =IF(TRUE*ISNUMBER(G18)*(N(G18)>0)*(N(G18)<1),"⚠ En % : saisir 62 pour 62 %",IF(G18<>"","✔ Renseigné",IF(OR(COUNTIFS(P_Criteres!$F$5:$F$64,B18,P_Criteres!$G$5:$G$64,"Oui")>0,COUNTIFS(P_Criteres!$F$5:$F$64,B18,P_Criteres!$K$5:$K$64,"Oui")>0,B18=P_ExtraKey),"⚠ Manquant — décisionnel","○ Non renseigné"))) -> ✔ Renseigné
A19: D2 — Qualité intrinsèque du projet | B19: land_permits_status | C19: Foncier & autorisations | D19: QUAL | E19: Titre purgé + autorisations définitives | G19: =IF(E19<>"",IF(SUMPRODUCT((P_Baremes!$A$5:$A$400="D2C1")*(P_Baremes!$F$5:$F$400=E19))>0,INDEX(P_Baremes!$C$5:$C$400,SUMPRODUCT(MAX((P_Baremes!$A$5:$A$400="D2C1")*(P_Baremes!$F$5:$F$400=E19)*(ROW(P_Baremes!$A$5:$A$400)-4)))),E19),IF(F19="","",F19)) -> definitives | H19: choisir dans la liste | I19: =IF(FALSE*ISNUMBER(G19)*(N(G19)>0)*(N(G19)<1),"⚠ En % : saisir 62 pour 62 %",IF(AND(E19<>"",COUNTIFS(P_Baremes!$A$5:$A$400,"D2C1",P_Baremes!$C$5:$C$400,G19)=0),"⚠ Valeur hors liste",IF(G19<>"","✔ Renseigné",IF(OR(COUNTIFS(P_Criteres!$F$5:$F$64,B19,P_Criteres!$G$5:$G$64,"Oui")>0,COUNTIFS(P_Criteres!$F$5:$F$64,B19,P_Criteres!$K$5:$K$64,"Oui")>0,B19=P_ExtraKey),"⚠ Manquant — décisionnel","○ Non renseigné")))) -> ✔ Renseigné
A20: D2 — Qualité intrinsèque du projet | B20: market_positioning | C20: Marché & positionnement | D20: QUAL | E20: Aligné / forte demande | G20: =IF(E20<>"",IF(SUMPRODUCT((P_Baremes!$A$5:$A$400="D2C2")*(P_Baremes!$F$5:$F$400=E20))>0,INDEX(P_Baremes!$C$5:$C$400,SUMPRODUCT(MAX((P_Baremes!$A$5:$A$400="D2C2")*(P_Baremes!$F$5:$F$400=E20)*(ROW(P_Baremes!$A$5:$A$400)-4)))),E20),IF(F20="","",F20)) -> aligne | H20: choisir dans la liste | I20: =IF(FALSE*ISNUMBER(G20)*(N(G20)>0)*(N(G20)<1),"⚠ En % : saisir 62 pour 62 %",IF(AND(E20<>"",COUNTIFS(P_Baremes!$A$5:$A$400,"D2C2",P_Baremes!$C$5:$C$400,G20)=0),"⚠ Valeur hors liste",IF(G20<>"","✔ Renseigné",IF(OR(COUNTIFS(P_Criteres!$F$5:$F$64,B20,P_Criteres!$G$5:$G$64,"Oui")>0,COUNTIFS(P_Criteres!$F$5:$F$64,B20,P_Criteres!$K$5:$K$64,"Oui")>0,B20=P_ExtraKey),"⚠ Manquant — décisionnel","○ Non renseigné")))) -> ✔ Renseigné
A21: D2 — Qualité intrinsèque du projet | B21: technical_complexity | C21: Complexité technique | D21: QUAL | E21: Standard | G21: =IF(E21<>"",IF(SUMPRODUCT((P_Baremes!$A$5:$A$400="D2C3")*(P_Baremes!$F$5:$F$400=E21))>0,INDEX(P_Baremes!$C$5:$C$400,SUMPRODUCT(MAX((P_Baremes!$A$5:$A$400="D2C3")*(P_Baremes!$F$5:$F$400=E21)*(ROW(P_Baremes!$A$5:$A$400)-4)))),E21),IF(F21="","",F21)) -> standard | H21: choisir dans la liste | I21: =IF(FALSE*ISNUMBER(G21)*(N(G21)>0)*(N(G21)<1),"⚠ En % : saisir 62 pour 62 %",IF(AND(E21<>"",COUNTIFS(P_Baremes!$A$5:$A$400,"D2C3",P_Baremes!$C$5:$C$400,G21)=0),"⚠ Valeur hors liste",IF(G21<>"","✔ Renseigné",IF(OR(COUNTIFS(P_Criteres!$F$5:$F$64,B21,P_Criteres!$G$5:$G$64,"Oui")>0,COUNTIFS(P_Criteres!$F$5:$F$64,B21,P_Criteres!$K$5:$K$64,"Oui")>0,B21=P_ExtraKey),"⚠ Manquant — décisionnel","○ Non renseigné")))) -> ✔ Renseigné
A22: D2 — Qualité intrinsèque du projet | B22: progress_vs_plan | C22: Avancement vs planning | D22: NUM | E22: 100 | G22: =IF(E22<>"",E22,IF(F22="","",F22)) -> 100 | H22: % (ex. 100) | I22: =IF(TRUE*ISNUMBER(G22)*(N(G22)>0)*(N(G22)<1),"⚠ En % : saisir 62 pour 62 %",IF(G22<>"","✔ Renseigné",IF(OR(COUNTIFS(P_Criteres!$F$5:$F$64,B22,P_Criteres!$G$5:$G$64,"Oui")>0,COUNTIFS(P_Criteres!$F$5:$F$64,B22,P_Criteres!$K$5:$K$64,"Oui")>0,B22=P_ExtraKey),"⚠ Manquant — décisionnel","○ Non renseigné"))) -> ✔ Renseigné
A23: D2 — Qualité intrinsèque du projet | B23: sav_litigation | C23: Litiges clients / SAV | D23: QUAL | E23: Faible | G23: =IF(E23<>"",IF(SUMPRODUCT((P_Baremes!$A$5:$A$400="D2C5")*(P_Baremes!$F$5:$F$400=E23))>0,INDEX(P_Baremes!$C$5:$C$400,SUMPRODUCT(MAX((P_Baremes!$A$5:$A$400="D2C5")*(P_Baremes!$F$5:$F$400=E23)*(ROW(P_Baremes!$A$5:$A$400)-4)))),E23),IF(F23="","",F23)) -> faible | H23: choisir dans la liste | I23: =IF(FALSE*ISNUMBER(G23)*(N(G23)>0)*(N(G23)<1),"⚠ En % : saisir 62 pour 62 %",IF(AND(E23<>"",COUNTIFS(P_Baremes!$A$5:$A$400,"D2C5",P_Baremes!$C$5:$C$400,G23)=0),"⚠ Valeur hors liste",IF(G23<>"","✔ Renseigné",IF(OR(COUNTIFS(P_Criteres!$F$5:$F$64,B23,P_Criteres!$G$5:$G$64,"Oui")>0,COUNTIFS(P_Criteres!$F$5:$F$64,B23,P_Criteres!$K$5:$K$64,"Oui")>0,B23=P_ExtraKey),"⚠ Manquant — décisionnel","○ Non renseigné")))) -> ✔ Renseigné
A24: D2 — Qualité intrinsèque du projet | B24: macro_sensitivity | C24: Sensibilité macro / subvention | D24: QUAL | E24: Faible | G24: =IF(E24<>"",IF(SUMPRODUCT((P_Baremes!$A$5:$A$400="D2C6")*(P_Baremes!$F$5:$F$400=E24))>0,INDEX(P_Baremes!$C$5:$C$400,SUMPRODUCT(MAX((P_Baremes!$A$5:$A$400="D2C6")*(P_Baremes!$F$5:$F$400=E24)*(ROW(P_Baremes!$A$5:$A$400)-4)))),E24),IF(F24="","",F24)) -> faible | H24: choisir dans la liste | I24: =IF(FALSE*ISNUMBER(G24)*(N(G24)>0)*(N(G24)<1),"⚠ En % : saisir 62 pour 62 %",IF(AND(E24<>"",COUNTIFS(P_Baremes!$A$5:$A$400,"D2C6",P_Baremes!$C$5:$C$400,G24)=0),"⚠ Valeur hors liste",IF(G24<>"","✔ Renseigné",IF(OR(COUNTIFS(P_Criteres!$F$5:$F$64,B24,P_Criteres!$G$5:$G$64,"Oui")>0,COUNTIFS(P_Criteres!$F$5:$F$64,B24,P_Criteres!$K$5:$K$64,"Oui")>0,B24=P_ExtraKey),"⚠ Manquant — décisionnel","○ Non renseigné")))) -> ✔ Renseigné
A25: D2 — Qualité intrinsèque du projet | B25: land_cost_ratio | C25: Coût foncier / CA | D25: NUM | E25: 22 | G25: =IF(E25<>"",E25,IF(F25="","",F25)) -> 22 | H25: % (ex. 22) | I25: =IF(TRUE*ISNUMBER(G25)*(N(G25)>0)*(N(G25)<1),"⚠ En % : saisir 62 pour 62 %",IF(G25<>"","✔ Renseigné",IF(OR(COUNTIFS(P_Criteres!$F$5:$F$64,B25,P_Criteres!$G$5:$G$64,"Oui")>0,COUNTIFS(P_Criteres!$F$5:$F$64,B25,P_Criteres!$K$5:$K$64,"Oui")>0,B25=P_ExtraKey),"⚠ Manquant — décisionnel","○ Non renseigné"))) -> ✔ Renseigné
A26: D2 — Qualité intrinsèque du projet | B26: authorization_completeness_pct | C26: Chaîne d'autorisations (complétude) | D26: NUM | E26: 100 | F26: =IF(Calc_Actif,IF(Calculateurs!C35,Calculateurs!C33,""),"") | G26: =IF(E26<>"",E26,IF(F26="","",F26)) -> 100 | H26: % — calculé par l'onglet Calculateurs ; votre saisie prime | I26: =IF(TRUE*ISNUMBER(G26)*(N(G26)>0)*(N(G26)<1),"⚠ En % : saisir 62 pour 62 %",IF(G26<>"","✔ Renseigné",IF(OR(COUNTIFS(P_Criteres!$F$5:$F$64,B26,P_Criteres!$G$5:$G$64,"Oui")>0,COUNTIFS(P_Criteres!$F$5:$F$64,B26,P_Criteres!$K$5:$K$64,"Oui")>0,B26=P_ExtraKey),"⚠ Manquant — décisionnel","○ Non renseigné"))) -> ✔ Renseigné
A27: D2 — Qualité intrinsèque du projet | B27: regional_market_tension | C27: Tension du marché régional | D27: QUAL | E27: Marché porteur (demande soutenue) | G27: =IF(E27<>"",IF(SUMPRODUCT((P_Baremes!$A$5:$A$400="D2C9")*(P_Baremes!$F$5:$F$400=E27))>0,INDEX(P_Baremes!$C$5:$C$400,SUMPRODUCT(MAX((P_Baremes!$A$5:$A$400="D2C9")*(P_Baremes!$F$5:$F$400=E27)*(ROW(P_Baremes!$A$5:$A$400)-4)))),E27),IF(F27="","",F27)) -> porteur | H27: choisir dans la liste | I27: =IF(FALSE*ISNUMBER(G27)*(N(G27)>0)*(N(G27)<1),"⚠ En % : saisir 62 pour 62 %",IF(AND(E27<>"",COUNTIFS(P_Baremes!$A$5:$A$400,"D2C9",P_Baremes!$C$5:$C$400,G27)=0),"⚠ Valeur hors liste",IF(G27<>"","✔ Renseigné",IF(OR(COUNTIFS(P_Criteres!$F$5:$F$64,B27,P_Criteres!$G$5:$G$64,"Oui")>0,COUNTIFS(P_Criteres!$F$5:$F$64,B27,P_Criteres!$K$5:$K$64,"Oui")>0,B27=P_ExtraKey),"⚠ Manquant — décisionnel","○ Non renseigné")))) -> ✔ Renseigné
A28: D2 — Qualité intrinsèque du projet | B28: contractor_quality | C28: Entreprise de travaux et garanties de marché | D28: QUAL | E28: Entreprise qualifiée et classée, marché forfaitaire avec caution de bonne exécution et retenue de garantie | G28: =IF(E28<>"",IF(SUMPRODUCT((P_Baremes!$A$5:$A$400="D2C10")*(P_Baremes!$F$5:$F$400=E28))>0,INDEX(P_Baremes!$C$5:$C$400,SUMPRODUCT(MAX((P_Baremes!$A$5:$A$400="D2C10")*(P_Baremes!$F$5:$F$400=E28)*(ROW(P_Baremes!$A$5:$A$400)-4)))),E28),IF(F28="","",F28)) -> qualifiee_garantie | H28: choisir dans la liste | I28: =IF(FALSE*ISNUMBER(G28)*(N(G28)>0)*(N(G28)<1),"⚠ En % : saisir 62 pour 62 %",IF(AND(E28<>"",COUNTIFS(P_Baremes!$A$5:$A$400,"D2C10",P_Baremes!$C$5:$C$400,G28)=0),"⚠ Valeur hors liste",IF(G28<>"","✔ Renseigné",IF(OR(COUNTIFS(P_Criteres!$F$5:$F$64,B28,P_Criteres!$G$5:$G$64,"Oui")>0,COUNTIFS(P_Criteres!$F$5:$F$64,B28,P_Criteres!$K$5:$K$64,"Oui")>0,B28=P_ExtraKey),"⚠ Manquant — décisionnel","○ Non renseigné")))) -> ✔ Renseigné
A29: D2 — Qualité intrinsèque du projet | B29: equipment_unbudgeted_pct | C29: Équipements exigés non budgétés (% du coût) | D29: NUM | E29: 0 | F29: =IF(Calc_Actif,Calculateurs!C173,"") | G29: =IF(E29<>"",E29,IF(F29="","",F29)) -> 0 | H29: % du coût — calculé par l'onglet Calculateurs ; votre saisie prime | I29: =IF(TRUE*ISNUMBER(G29)*(N(G29)>0)*(N(G29)<1),"⚠ En % : saisir 62 pour 62 %",IF(G29<>"","✔ Renseigné",IF(OR(COUNTIFS(P_Criteres!$F$5:$F$64,B29,P_Criteres!$G$5:$G$64,"Oui")>0,COUNTIFS(P_Criteres!$F$5:$F$64,B29,P_Criteres!$K$5:$K$64,"Oui")>0,B29=P_ExtraKey),"⚠ Manquant — décisionnel","○ Non renseigné"))) -> ✔ Renseigné
A30: D2 — Qualité intrinsèque du projet | B30: tranche_dependency | C30: Autonomie du périmètre financé (tranche) | D30: QUAL | E30: Financement du programme entier | G30: =IF(E30<>"",IF(SUMPRODUCT((P_Baremes!$A$5:$A$400="D2C12")*(P_Baremes!$F$5:$F$400=E30))>0,INDEX(P_Baremes!$C$5:$C$400,SUMPRODUCT(MAX((P_Baremes!$A$5:$A$400="D2C12")*(P_Baremes!$F$5:$F$400=E30)*(ROW(P_Baremes!$A$5:$A$400)-4)))),E30),IF(F30="","",F30)) -> programme_entier | H30: choisir dans la liste | I30: =IF(FALSE*ISNUMBER(G30)*(N(G30)>0)*(N(G30)<1),"⚠ En % : saisir 62 pour 62 %",IF(AND(E30<>"",COUNTIFS(P_Baremes!$A$5:$A$400,"D2C12",P_Baremes!$C$5:$C$400,G30)=0),"⚠ Valeur hors liste",IF(G30<>"","✔ Renseigné",IF(OR(COUNTIFS(P_Criteres!$F$5:$F$64,B30,P_Criteres!$G$5:$G$64,"Oui")>0,COUNTIFS(P_Criteres!$F$5:$F$64,B30,P_Criteres!$K$5:$K$64,"Oui")>0,B30=P_ExtraKey),"⚠ Manquant — décisionnel","○ Non renseigné")))) -> ✔ Renseigné
A31: D3 — Commercial & Cash-flow | B31: pre_sale_rate | C31: Préventes sécurisées (encaissées / CA) | D31: NUM | E31: 62 | G31: =IF(E31<>"",E31,IF(F31="","",F31)) -> 62 | H31: % (ex. 62) | I31: =IF(TRUE*ISNUMBER(G31)*(N(G31)>0)*(N(G31)<1),"⚠ En % : saisir 62 pour 62 %",IF(G31<>"","✔ Renseigné",IF(OR(COUNTIFS(P_Criteres!$F$5:$F$64,B31,P_Criteres!$G$5:$G$64,"Oui")>0,COUNTIFS(P_Criteres!$F$5:$F$64,B31,P_Criteres!$K$5:$K$64,"Oui")>0,B31=P_ExtraKey),"⚠ Manquant — décisionnel","○ Non renseigné"))) -> ✔ Renseigné
A32: D3 — Commercial & Cash-flow | B32: sales_vs_plan | C32: Ventes vs planning | D32: NUM | E32: 100 | G32: =IF(E32<>"",E32,IF(F32="","",F32)) -> 100 | H32: % (ex. 100) | I32: =IF(TRUE*ISNUMBER(G32)*(N(G32)>0)*(N(G32)<1),"⚠ En % : saisir 62 pour 62 %",IF(G32<>"","✔ Renseigné",IF(OR(COUNTIFS(P_Criteres!$F$5:$F$64,B32,P_Criteres!$G$5:$G$64,"Oui")>0,COUNTIFS(P_Criteres!$F$5:$F$64,B32,P_Criteres!$K$5:$K$64,"Oui")>0,B32=P_ExtraKey),"⚠ Manquant — décisionnel","○ Non renseigné"))) -> ✔ Renseigné
A33: D3 — Commercial & Cash-flow | B33: dso_days | C33: DSO (jours) | D33: NUM | E33: 90 | G33: =IF(E33<>"",E33,IF(F33="","",F33)) -> 90 | H33: jours (ex. 90) | I33: =IF(FALSE*ISNUMBER(G33)*(N(G33)>0)*(N(G33)<1),"⚠ En % : saisir 62 pour 62 %",IF(G33<>"","✔ Renseigné",IF(OR(COUNTIFS(P_Criteres!$F$5:$F$64,B33,P_Criteres!$G$5:$G$64,"Oui")>0,COUNTIFS(P_Criteres!$F$5:$F$64,B33,P_Criteres!$K$5:$K$64,"Oui")>0,B33=P_ExtraKey),"⚠ Manquant — décisionnel","○ Non renseigné"))) -> ✔ Renseigné
A34: D3 — Commercial & Cash-flow | B34: cash_coverage | C34: Cash coverage (cash / échéances) | D34: NUM | E34: 0.99 | G34: =IF(E34<>"",E34,IF(F34="","",F34)) -> 0.99 | H34: ratio (ex. 1,2) | I34: =IF(FALSE*ISNUMBER(G34)*(N(G34)>0)*(N(G34)<1),"⚠ En % : saisir 62 pour 62 %",IF(G34<>"","✔ Renseigné",IF(OR(COUNTIFS(P_Criteres!$F$5:$F$64,B34,P_Criteres!$G$5:$G$64,"Oui")>0,COUNTIFS(P_Criteres!$F$5:$F$64,B34,P_Criteres!$K$5:$K$64,"Oui")>0,B34=P_ExtraKey),"⚠ Manquant — décisionnel","○ Non renseigné"))) -> ✔ Renseigné
A35: D3 — Commercial & Cash-flow | B35: funding_gap_pct | C35: Impasse brute | D35: NUM | E35: 0 | G35: =IF(E35<>"",E35,IF(F35="","",F35)) -> 0 | H35: % (ex. 0) | I35: =IF(TRUE*ISNUMBER(G35)*(N(G35)>0)*(N(G35)<1),"⚠ En % : saisir 62 pour 62 %",IF(G35<>"","✔ Renseigné",IF(OR(COUNTIFS(P_Criteres!$F$5:$F$64,B35,P_Criteres!$G$5:$G$64,"Oui")>0,COUNTIFS(P_Criteres!$F$5:$F$64,B35,P_Criteres!$K$5:$K$64,"Oui")>0,B35=P_ExtraKey),"⚠ Manquant — décisionnel","○ Non renseigné"))) -> ✔ Renseigné
A36: D3 — Commercial & Cash-flow | B36: stock_rotation_months | C36: Rotation stock (mois) | D36: NUM | E36: 16 | G36: =IF(E36<>"",E36,IF(F36="","",F36)) -> 16 | H36: mois (ex. 16) | I36: =IF(FALSE*ISNUMBER(G36)*(N(G36)>0)*(N(G36)<1),"⚠ En % : saisir 62 pour 62 %",IF(G36<>"","✔ Renseigné",IF(OR(COUNTIFS(P_Criteres!$F$5:$F$64,B36,P_Criteres!$G$5:$G$64,"Oui")>0,COUNTIFS(P_Criteres!$F$5:$F$64,B36,P_Criteres!$K$5:$K$64,"Oui")>0,B36=P_ExtraKey),"⚠ Manquant — décisionnel","○ Non renseigné"))) -> ✔ Renseigné
A37: D3 — Commercial & Cash-flow | B37: stressed_margin_pct | C37: Marge brute stressée (prix -10%) | D37: NUM | E37: 18 | G37: =IF(E37<>"",E37,IF(F37="","",F37)) -> 18 | H37: % (ex. 18) | I37: =IF(TRUE*ISNUMBER(G37)*(N(G37)>0)*(N(G37)<1),"⚠ En % : saisir 62 pour 62 %",IF(G37<>"","✔ Renseigné",IF(OR(COUNTIFS(P_Criteres!$F$5:$F$64,B37,P_Criteres!$G$5:$G$64,"Oui")>0,COUNTIFS(P_Criteres!$F$5:$F$64,B37,P_Criteres!$K$5:$K$64,"Oui")>0,B37=P_ExtraKey),"⚠ Manquant — décisionnel","○ Non renseigné"))) -> ✔ Renseigné
A38: D3 — Commercial & Cash-flow | B38: secured_sales_rate | C38: Ventes sécurisées (financement acquéreur) | D38: NUM | E38: 55 | F38: =IF(Calc_Actif,Calculateurs!C85,"") | G38: =IF(E38<>"",E38,IF(F38="","",F38)) -> 55 | H38: % — calculé par l'onglet Calculateurs ; votre saisie prime | I38: =IF(TRUE*ISNUMBER(G38)*(N(G38)>0)*(N(G38)<1),"⚠ En % : saisir 62 pour 62 %",IF(G38<>"","✔ Renseigné",IF(OR(COUNTIFS(P_Criteres!$F$5:$F$64,B38,P_Criteres!$G$5:$G$64,"Oui")>0,COUNTIFS(P_Criteres!$F$5:$F$64,B38,P_Criteres!$K$5:$K$64,"Oui")>0,B38=P_ExtraKey),"⚠ Manquant — décisionnel","○ Non renseigné"))) -> ✔ Renseigné
A39: D3 — Commercial & Cash-flow | B39: slow_liquidity_share_pct | C39: Part du CA en produits à écoulement lent | D39: NUM | E39: 5 | F39: =IF(Calc_Actif,Calculateurs!C181,"") | G39: =IF(E39<>"",E39,IF(F39="","",F39)) -> 5 | H39: % du CA — calculé par l'onglet Calculateurs ; votre saisie prime | I39: =IF(TRUE*ISNUMBER(G39)*(N(G39)>0)*(N(G39)<1),"⚠ En % : saisir 62 pour 62 %",IF(G39<>"","✔ Renseigné",IF(OR(COUNTIFS(P_Criteres!$F$5:$F$64,B39,P_Criteres!$G$5:$G$64,"Oui")>0,COUNTIFS(P_Criteres!$F$5:$F$64,B39,P_Criteres!$K$5:$K$64,"Oui")>0,B39=P_ExtraKey),"⚠ Manquant — décisionnel","○ Non renseigné"))) -> ✔ Renseigné
A40: D3 — Commercial & Cash-flow | B40: cancellation_rate_pct | C40: Taux de désistement des réservations | D40: NUM | E40: 3 | F40: =IF(Calc_Actif,Calculateurs!C185,"") | G40: =IF(E40<>"",E40,IF(F40="","",F40)) -> 3 | H40: % — calculé par l'onglet Calculateurs ; votre saisie prime | I40: =IF(TRUE*ISNUMBER(G40)*(N(G40)>0)*(N(G40)<1),"⚠ En % : saisir 62 pour 62 %",IF(G40<>"","✔ Renseigné",IF(OR(COUNTIFS(P_Criteres!$F$5:$F$64,B40,P_Criteres!$G$5:$G$64,"Oui")>0,COUNTIFS(P_Criteres!$F$5:$F$64,B40,P_Criteres!$K$5:$K$64,"Oui")>0,B40=P_ExtraKey),"⚠ Manquant — décisionnel","○ Non renseigné"))) -> ✔ Renseigné
A41: D4 — Structuration financière & LGD | B41: gross_margin_pct | C41: Marge brute (CA - coûts directs)/CA | D41: NUM | E41: 27 | G41: =IF(E41<>"",E41,IF(F41="","",F41)) -> 27 | H41: % (ex. 27) | I41: =IF(TRUE*ISNUMBER(G41)*(N(G41)>0)*(N(G41)<1),"⚠ En % : saisir 62 pour 62 %",IF(G41<>"","✔ Renseigné",IF(OR(COUNTIFS(P_Criteres!$F$5:$F$64,B41,P_Criteres!$G$5:$G$64,"Oui")>0,COUNTIFS(P_Criteres!$F$5:$F$64,B41,P_Criteres!$K$5:$K$64,"Oui")>0,B41=P_ExtraKey),"⚠ Manquant — décisionnel","○ Non renseigné"))) -> ✔ Renseigné
...

Sheet Fiche
A1: ="Fiche de scoring — "&IF(Saisie!C4="","(dossier sans référence)",Saisie!C4) -> Fiche de scoring — EXEMPLE
A2: =IF(Saisie!C5="","",Saisie!C5) -> Dossier d'exemple — à remplacer (ruban « Scoring PI » › Nouveau dossier)
A3: ="Modèle PI_PROMOTION "&P_Version&" · outil 5.1" -> Modèle PI_PROMOTION v5.0.0 · outil 5.1 | E3: Calculé le | F3: =TODAY() -> 46300
A5: Score final / 100 | B5: Décision | D5: Classe interne
A6: =Res_ScoreFinal -> 68.46 | B6: =IFERROR(VLOOKUP(Res_Decision,P_DecTbl,2,FALSE),Res_Decision) -> Favorable sous conditions | D6: =Res_ClasseInt -> Surveillance
A9: Principaux éléments
A10: Segment · zone | B10: =IF(Saisie!C6="","(segment non renseigné)",Saisie!C6)&" · "&IF(Saisie!C7="","(zone non renseignée)",Saisie!C7) -> Moyen-haut standing · Casablanca — centre
A11: Classe réglementaire BAM | B11: =IF(Saisie!C8="","(non renseignée — dossier incomplet)",IFERROR(VLOOKUP(Saisie!C8,P_Classes,2,FALSE),Saisie!C8)) -> Créance saine
A12: Note économique · note de sûretés | B12: =FIXED(Res_EcoScore,1)&" / 100 · sûretés : "&IF(ISNUMBER(Res_GuarScore),FIXED(Res_GuarScore,1)&" / 100","n/a") -> 92.5 / 100 · sûretés : 100.0 / 100
A13: Malus des alertes | B13: =FIXED(Res_Malus,0)&" point(s)" -> 25 point(s)
A14: PD indicative (non calibrée) | B14: =IF(ISNUMBER(Res_PD),FIXED(Res_PD*100,1)&" %","n/d (dossier incomplet)") -> 3.7 %
A15: Critères renseignés | B15: =Saisie!I7 -> 37 / 37
A16: Données décisionnelles manquantes | B16: =IF(Res_Manquantes="","Aucune",Res_Manquantes) -> Aucune
A17: Conditions à lever | B17: =IF(Res_Conditions="","Aucune",Res_Conditions) -> Aucune
A18: Alertes déclenchées | B18: =IF(Res_AlertesLib="","Aucune",Res_AlertesLib) -> Cash coverage < 1,0x
A19: Retour en comité requis | B19: =IF(Res_Comite,"Oui","Non") -> Non
A21: Scores par domaine
A22: Domaine | B22: Score / 100 | C22: Poids | D22: Contribution
A23: =IF(Resultat!$A$32="","",Resultat!$A$32&" — "&Resultat!$B$32) -> D1 — Sponsor & Gouvernance | B23: =IF(Resultat!$A$32="","",Resultat!$C$32) -> 100 | C23: =IF(Resultat!$A$32="","",Resultat!$D$32) -> 0.25 | D23: =IF(Resultat!$A$32="","",Resultat!$E$32) -> 25
A24: =IF(Resultat!$A$33="","",Resultat!$A$33&" — "&Resultat!$B$33) -> D2 — Qualité intrinsèque du projet | B24: =IF(Resultat!$A$33="","",Resultat!$C$33) -> 100 | C24: =IF(Resultat!$A$33="","",Resultat!$D$33) -> 0.2 | D24: =IF(Resultat!$A$33="","",Resultat!$E$33) -> 20
A25: =IF(Resultat!$A$34="","",Resultat!$A$34&" — "&Resultat!$B$34) -> D3 — Commercial & Cash-flow | B25: =IF(Resultat!$A$34="","",Resultat!$C$34) -> 82 | C25: =IF(Resultat!$A$34="","",Resultat!$D$34) -> 0.31 | D25: =IF(Resultat!$A$34="","",Resultat!$E$34) -> 25.42
A26: =IF(Resultat!$A$35="","",Resultat!$A$35&" — "&Resultat!$B$35) -> D4 — Structuration financière & LGD | B26: =IF(Resultat!$A$35="","",Resultat!$C$35) -> 96 | C26: =IF(Resultat!$A$35="","",Resultat!$D$35) -> 0.24 | D26: =IF(Resultat!$A$35="","",Resultat!$E$35) -> 23.04
A27: =IF(Resultat!$A$36="","",Resultat!$A$36&" — "&Resultat!$B$36) | B27: =IF(Resultat!$A$36="","",Resultat!$C$36) | C27: =IF(Resultat!$A$36="","",Resultat!$D$36) | D27: =IF(Resultat!$A$36="","",Resultat!$E$36)
A28: =IF(Resultat!$A$37="","",Resultat!$A$37&" — "&Resultat!$B$37) | B28: =IF(Resultat!$A$37="","",Resultat!$C$37) | C28: =IF(Resultat!$A$37="","",Resultat!$D$37) | D28: =IF(Resultat!$A$37="","",Resultat!$E$37)
A29: =IF(Resultat!$A$38="","",Resultat!$A$38&" — "&Resultat!$B$38) | B29: =IF(Resultat!$A$38="","",Resultat!$C$38) | C29: =IF(Resultat!$A$38="","",Resultat!$D$38) | D29: =IF(Resultat!$A$38="","",Resultat!$E$38)
A30: =IF(Resultat!$A$39="","",Resultat!$A$39&" — "&Resultat!$B$39) | B30: =IF(Resultat!$A$39="","",Resultat!$C$39) | C30: =IF(Resultat!$A$39="","",Resultat!$D$39) | D30: =IF(Resultat!$A$39="","",Resultat!$E$39)
A32: Points d'attention — les 5 notes les plus basses
A33: Critère | B33: Domaine | C33: Valeur retenue | E33: Note / 10
A34: =IF(I34="","",INDEX(Resultat!$C$44:$C$103,I34)) -> Cash coverage (cash / échéances) | B34: =IF(I34="","",IFERROR(INDEX(P_DomNoms,MATCH(INDEX(Resultat!$B$44:$B$103,I34),P_DomCodes,0)),"")) -> Commercial & Cash-flow | C34: =IF(I34="","",INDEX(Resultat!$V$44:$V$103,I34)) -> 0.99 | E34: =IF(I34="","",INDEX(Resultat!$F$44:$F$103,I34)) -> 1 | H34: =IFERROR(SMALL(Resultat!$U$44:$U$103,1),"") -> 1.000065 | I34: =IF(H34="","",MATCH(H34,Resultat!$U$44:$U$103,0)) -> 22
A35: =IF(I35="","",INDEX(Resultat!$C$44:$C$103,I35)) -> LTC (dette / coût total) | B35: =IF(I35="","",IFERROR(INDEX(P_DomNoms,MATCH(INDEX(Resultat!$B$44:$B$103,I35),P_DomCodes,0)),"")) -> Structuration financière & LGD | C35: =IF(I35="","",INDEX(Resultat!$V$44:$V$103,I35)) -> 61 | E35: =IF(I35="","",INDEX(Resultat!$F$44:$F$103,I35)) -> 6 | H35: =IFERROR(SMALL(Resultat!$U$44:$U$103,2),"") -> 6.000073 | I35: =IF(H35="","",MATCH(H35,Resultat!$U$44:$U$103,0)) -> 30
A36: =IF(I36="","",INDEX(Resultat!$C$44:$C$103,I36)) -> Projets similaires livrés (5 ans) | B36: =IF(I36="","",IFERROR(INDEX(P_DomNoms,MATCH(INDEX(Resultat!$B$44:$B$103,I36),P_DomCodes,0)),"")) -> Sponsor & Gouvernance | C36: =IF(I36="","",INDEX(Resultat!$V$44:$V$103,I36)) -> 8 | E36: =IF(I36="","",INDEX(Resultat!$F$44:$F$103,I36)) -> 10 | H36: =IFERROR(SMALL(Resultat!$U$44:$U$103,3),"") -> 10.000044 | I36: =IF(H36="","",MATCH(H36,Resultat!$U$44:$U$103,0)) -> 1
A37: =IF(I37="","",INDEX(Resultat!$C$44:$C$103,I37)) -> Gearing promoteur (dettes nettes / FP) | B37: =IF(I37="","",IFERROR(INDEX(P_DomNoms,MATCH(INDEX(Resultat!$B$44:$B$103,I37),P_DomCodes,0)),"")) -> Sponsor & Gouvernance | C37: =IF(I37="","",INDEX(Resultat!$V$44:$V$103,I37)) -> 85 | E37: =IF(I37="","",INDEX(Resultat!$F$44:$F$103,I37)) -> 10 | H37: =IFERROR(SMALL(Resultat!$U$44:$U$103,4),"") -> 10.000045 | I37: =IF(H37="","",MATCH(H37,Resultat!$U$44:$U$103,0)) -> 2
A38: =IF(I38="","",INDEX(Resultat!$C$44:$C$103,I38)) -> Gouvernance & structure juridique | B38: =IF(I38="","",IFERROR(INDEX(P_DomNoms,MATCH(INDEX(Resultat!$B$44:$B$103,I38),P_DomCodes,0)),"")) -> Sponsor & Gouvernance | C38: =IF(I38="","",INDEX(Resultat!$V$44:$V$103,I38)) -> Claire / structurée | E38: =IF(I38="","",INDEX(Resultat!$F$44:$F$103,I38)) -> 10 | H38: =IFERROR(SMALL(Resultat!$U$44:$U$103,5),"") -> 10.000046 | I38: =IF(H38="","",MATCH(H38,Resultat!$U$44:$U$103,0)) -> 3
A40: Outil indicatif. La décision officielle se prend dans l'application (circuit de validation, comité). Détail du calcul : onglet Resultat.

Sheet Calculateurs
A1: Calculateurs — alimentent automatiquement les données dérivées (Saisie, colonne « Valeur calculée »)
A2: Une valeur saisie directement dans l'onglet Saisie prime toujours sur ces calculs.
A4: A. Chaîne d'autorisations
A5: Nature du programme | B5: CONSTRUCTION
A7: Code | B7: Pièce | C7: Exigible | D7: Obtenue | E7: Bloque travaux | F7: Bloque livraison | G7: Manquante
A8: =IF(P_Referentiels!A6="","",P_Referentiels!A6) -> note_renseignement | B8: =IF(A8="","",P_Referentiels!B6) -> Note de renseignements urbanistiques | C8: =IF(A8="",FALSE,IF($B$5="LOTISSEMENT",P_Referentiels!D6,IF($B$5="CONSTRUCTION",P_Referentiels!E6,P_Referentiels!F6))="Oui") -> TRUE | E8: =IF(A8="",FALSE,P_Referentiels!G6="Oui") -> FALSE | F8: =IF(A8="",FALSE,P_Referentiels!H6="Oui") -> FALSE | G8: =AND(C8,D8<>"Oui") -> TRUE
A9: =IF(P_Referentiels!A7="","",P_Referentiels!A7) -> titre_foncier_purge | B9: =IF(A9="","",P_Referentiels!B7) -> Titre foncier purgé (sans inscription contraignante) | C9: =IF(A9="",FALSE,IF($B$5="LOTISSEMENT",P_Referentiels!D7,IF($B$5="CONSTRUCTION",P_Referentiels!E7,P_Referentiels!F7))="Oui") -> TRUE | E9: =IF(A9="",FALSE,P_Referentiels!G7="Oui") -> TRUE | F9: =IF(A9="",FALSE,P_Referentiels!H7="Oui") -> FALSE | G9: =AND(C9,D9<>"Oui") -> TRUE
A10: =IF(P_Referentiels!A8="","",P_Referentiels!A8) -> autorisation_lotir | B10: =IF(A10="","",P_Referentiels!B8) -> Autorisation de lotir | C10: =IF(A10="",FALSE,IF($B$5="LOTISSEMENT",P_Referentiels!D8,IF($B$5="CONSTRUCTION",P_Referentiels!E8,P_Referentiels!F8))="Oui") -> FALSE | E10: =IF(A10="",FALSE,P_Referentiels!G8="Oui") -> TRUE | F10: =IF(A10="",FALSE,P_Referentiels!H8="Oui") -> FALSE | G10: =AND(C10,D10<>"Oui") -> FALSE
A11: =IF(P_Referentiels!A9="","",P_Referentiels!A9) -> permis_construire | B11: =IF(A11="","",P_Referentiels!B9) -> Permis de construire | C11: =IF(A11="",FALSE,IF($B$5="LOTISSEMENT",P_Referentiels!D9,IF($B$5="CONSTRUCTION",P_Referentiels!E9,P_Referentiels!F9))="Oui") -> TRUE | E11: =IF(A11="",FALSE,P_Referentiels!G9="Oui") -> TRUE | F11: =IF(A11="",FALSE,P_Referentiels!H9="Oui") -> FALSE | G11: =AND(C11,D11<>"Oui") -> TRUE
A12: =IF(P_Referentiels!A10="","",P_Referentiels!A10) -> autorisation_morcellement | B12: =IF(A12="","",P_Referentiels!B10) -> Autorisation de morcellement / éclatement du titre | C12: =IF(A12="",FALSE,IF($B$5="LOTISSEMENT",P_Referentiels!D10,IF($B$5="CONSTRUCTION",P_Referentiels!E10,P_Referentiels!F10))="Oui") -> FALSE | E12: =IF(A12="",FALSE,P_Referentiels!G10="Oui") -> FALSE | F12: =IF(A12="",FALSE,P_Referentiels!H10="Oui") -> FALSE | G12: =AND(C12,D12<>"Oui") -> FALSE
A13: =IF(P_Referentiels!A11="","",P_Referentiels!A11) -> reception_provisoire | B13: =IF(A13="","",P_Referentiels!B11) -> Réception provisoire des travaux | C13: =IF(A13="",FALSE,IF($B$5="LOTISSEMENT",P_Referentiels!D11,IF($B$5="CONSTRUCTION",P_Referentiels!E11,P_Referentiels!F11))="Oui") -> TRUE | E13: =IF(A13="",FALSE,P_Referentiels!G11="Oui") -> FALSE | F13: =IF(A13="",FALSE,P_Referentiels!H11="Oui") -> TRUE | G13: =AND(C13,D13<>"Oui") -> TRUE
A14: =IF(P_Referentiels!A12="","",P_Referentiels!A12) -> permis_habiter | B14: =IF(A14="","",P_Referentiels!B12) -> Permis d'habiter | C14: =IF(A14="",FALSE,IF($B$5="LOTISSEMENT",P_Referentiels!D12,IF($B$5="CONSTRUCTION",P_Referentiels!E12,P_Referentiels!F12))="Oui") -> TRUE | E14: =IF(A14="",FALSE,P_Referentiels!G12="Oui") -> FALSE | F14: =IF(A14="",FALSE,P_Referentiels!H12="Oui") -> TRUE | G14: =AND(C14,D14<>"Oui") -> TRUE
A15: =IF(P_Referentiels!A13="","",P_Referentiels!A13) -> certificat_conformite | B15: =IF(A15="","",P_Referentiels!B13) -> Certificat de conformité | C15: =IF(A15="",FALSE,IF($B$5="LOTISSEMENT",P_Referentiels!D13,IF($B$5="CONSTRUCTION",P_Referentiels!E13,P_Referentiels!F13))="Oui") -> TRUE | E15: =IF(A15="",FALSE,P_Referentiels!G13="Oui") -> FALSE | F15: =IF(A15="",FALSE,P_Referentiels!H13="Oui") -> TRUE | G15: =AND(C15,D15<>"Oui") -> TRUE
A16: =IF(P_Referentiels!A14="","",P_Referentiels!A14) -> reception_definitive | B16: =IF(A16="","",P_Referentiels!B14) -> Réception définitive | C16: =IF(A16="",FALSE,IF($B$5="LOTISSEMENT",P_Referentiels!D14,IF($B$5="CONSTRUCTION",P_Referentiels!E14,P_Referentiels!F14))="Oui") -> TRUE | E16: =IF(A16="",FALSE,P_Referentiels!G14="Oui") -> FALSE | F16: =IF(A16="",FALSE,P_Referentiels!H14="Oui") -> FALSE | G16: =AND(C16,D16<>"Oui") -> TRUE
A17: =IF(P_Referentiels!A15="","",P_Referentiels!A15) | B17: =IF(A17="","",P_Referentiels!B15) | C17: =IF(A17="",FALSE,IF($B$5="LOTISSEMENT",P_Referentiels!D15,IF($B$5="CONSTRUCTION",P_Referentiels!E15,P_Referentiels!F15))="Oui") -> FALSE | E17: =IF(A17="",FALSE,P_Referentiels!G15="Oui") -> FALSE | F17: =IF(A17="",FALSE,P_Referentiels!H15="Oui") -> FALSE | G17: =AND(C17,D17<>"Oui") -> FALSE
A18: =IF(P_Referentiels!A16="","",P_Referentiels!A16) | B18: =IF(A18="","",P_Referentiels!B16) | C18: =IF(A18="",FALSE,IF($B$5="LOTISSEMENT",P_Referentiels!D16,IF($B$5="CONSTRUCTION",P_Referentiels!E16,P_Referentiels!F16))="Oui") -> FALSE | E18: =IF(A18="",FALSE,P_Referentiels!G16="Oui") -> FALSE | F18: =IF(A18="",FALSE,P_Referentiels!H16="Oui") -> FALSE | G18: =AND(C18,D18<>"Oui") -> FALSE
A19: =IF(P_Referentiels!A17="","",P_Referentiels!A17) | B19: =IF(A19="","",P_Referentiels!B17) | C19: =IF(A19="",FALSE,IF($B$5="LOTISSEMENT",P_Referentiels!D17,IF($B$5="CONSTRUCTION",P_Referentiels!E17,P_Referentiels!F17))="Oui") -> FALSE | E19: =IF(A19="",FALSE,P_Referentiels!G17="Oui") -> FALSE | F19: =IF(A19="",FALSE,P_Referentiels!H17="Oui") -> FALSE | G19: =AND(C19,D19<>"Oui") -> FALSE
... A31: =IF(P_Referentiels!A29="","",P_Referentiels!A29) | B31: =IF(A31="","",P_Referentiels!B29) | C31: =IF(A31="",FALSE,IF($B$5="LOTISSEMENT",P_Referentiels!D29,IF($B$5="CONSTRUCTION",P_Referentiels!E29,P_Referentiels!F29))="Oui") -> FALSE | E31: =IF(A31="",FALSE,P_Referentiels!G29="Oui") -> FALSE | F31: =IF(A31="",FALSE,P_Referentiels!H29="Oui") -> FALSE | G31: =AND(C31,D31<>"Oui") -> FALSE
A33: Complétude de la chaîne (%) | C33: =IF(SUMPRODUCT((C8:C31=TRUE)*1)=0,100,ROUND(SUMPRODUCT((C8:C31=TRUE)*(D8:D31="Oui"))/SUMPRODUCT((C8:C31=TRUE)*1)*100,2)) -> 0
A34: Verrou de travaux (pièce indispensable manquante) | C34: =SUMPRODUCT((G8:G31=TRUE)*(E8:E31=TRUE))>0 -> TRUE
A35: Saisie de la chaîne effectuée ? | C35: =COUNTIF(D8:D31,"Oui")+COUNTIF(D8:D31,"Non")>0 -> FALSE
A38: B. Ventes sécurisées (financement de l'acquéreur)
A39: Valeur commercialisable totale (MAD) | D39: vide = somme des prix des lots ci-dessous
A41: Lot | B41: Statut de financement acquéreur | C41: Prix (MAD) | D41: Engagé juridiquement | E41: Facteur | F41: Renseigné | G41: À risque
E42: =IF(B42="",0,IFERROR(VLOOKUP(B42,R_FinTbl,3,FALSE),0.2)) -> 0 | F42: =B42<>"" -> FALSE | G42: =AND(B42<>"",D42<>"Non",E42<=0.4) -> FALSE
E43: =IF(B43="",0,IFERROR(VLOOKUP(B43,R_FinTbl,3,FALSE),0.2)) -> 0 | F43: =B43<>"" -> FALSE | G43: =AND(B43<>"",D43<>"Non",E43<=0.4) -> FALSE
E44: =IF(B44="",0,IFERROR(VLOOKUP(B44,R_FinTbl,3,FALSE),0.2)) -> 0 | F44: =B44<>"" -> FALSE | G44: =AND(B44<>"",D44<>"Non",E44<=0.4) -> FALSE
E45: =IF(B45="",0,IFERROR(VLOOKUP(B45,R_FinTbl,3,FALSE),0.2)) -> 0 | F45: =B45<>"" -> FALSE | G45: =AND(B45<>"",D45<>"Non",E45<=0.4) -> FALSE
E46: =IF(B46="",0,IFERROR(VLOOKUP(B46,R_FinTbl,3,FALSE),0.2)) -> 0 | F46: =B46<>"" -> FALSE | G46: =AND(B46<>"",D46<>"Non",E46<=0.4) -> FALSE
E47: =IF(B47="",0,IFERROR(VLOOKUP(B47,R_FinTbl,3,FALSE),0.2)) -> 0 | F47: =B47<>"" -> FALSE | G47: =AND(B47<>"",D47<>"Non",E47<=0.4) -> FALSE
E48: =IF(B48="",0,IFERROR(VLOOKUP(B48,R_FinTbl,3,FALSE),0.2)) -> 0 | F48: =B48<>"" -> FALSE | G48: =AND(B48<>"",D48<>"Non",E48<=0.4) -> FALSE
E49: =IF(B49="",0,IFERROR(VLOOKUP(B49,R_FinTbl,3,FALSE),0.2)) -> 0 | F49: =B49<>"" -> FALSE | G49: =AND(B49<>"",D49<>"Non",E49<=0.4) -> FALSE
E50: =IF(B50="",0,IFERROR(VLOOKUP(B50,R_FinTbl,3,FALSE),0.2)) -> 0 | F50: =B50<>"" -> FALSE | G50: =AND(B50<>"",D50<>"Non",E50<=0.4) -> FALSE
E51: =IF(B51="",0,IFERROR(VLOOKUP(B51,R_FinTbl,3,FALSE),0.2)) -> 0 | F51: =B51<>"" -> FALSE | G51: =AND(B51<>"",D51<>"Non",E51<=0.4) -> FALSE
E52: =IF(B52="",0,IFERROR(VLOOKUP(B52,R_FinTbl,3,FALSE),0.2)) -> 0 | F52: =B52<>"" -> FALSE | G52: =AND(B52<>"",D52<>"Non",E52<=0.4) -> FALSE
E53: =IF(B53="",0,IFERROR(VLOOKUP(B53,R_FinTbl,3,FALSE),0.2)) -> 0 | F53: =B53<>"" -> FALSE | G53: =AND(B53<>"",D53<>"Non",E53<=0.4) -> FALSE
... E81: =IF(B81="",0,IFERROR(VLOOKUP(B81,R_FinTbl,3,FALSE),0.2)) -> 0 | F81: =B81<>"" -> FALSE | G81: =AND(B81<>"",D81<>"Non",E81<=0.4) -> FALSE
A83: Chiffre d'affaires engagé (MAD) | C83: =SUMPRODUCT((F42:F81=TRUE)*(D42:D81<>"Non")*C42:C81) -> 0
A84: Chiffre d'affaires sécurisé (MAD) | C84: =SUMPRODUCT((F42:F81=TRUE)*(D42:D81<>"Non")*C42:C81*E42:E81) -> 0
A85: Taux de ventes sécurisées (%) | C85: =IF(SUMPRODUCT((F42:F81=TRUE)*1)=0,"",IF(IF(C39="",SUM(C42:C81),C39)>0,ROUND(C84/IF(C39="",SUM(C42:C81),C39)*100,2),""))
...

Sheet Portefeuille
A1: Scoring de portefeuille
A2: Une ligne par dossier (ruban › Enregistrer le dossier ajoute ou met à jour la ligne du dossier en cours ; Ouvrir un dossier le recharge). Ruban › Scorer le portefeuille remplit les colonnes de résultat à droite. Booléens : Oui / Non.
A3: Identité | F3: Données d'entrée (mêmes clés que l'onglet Saisie)
A4: Référence | B4: Nom du projet | C4: Segment | D4: Zone | E4: Classe BAM | F4: promoter_completed_projects | G4: promoter_gearing | H4: governance_quality | I4: mono_project_concentration | J4: promoter_type | K4: equity_injected_ratio | L4: land_permits_status | M4: market_positioning | N4: technical_complexity | O4: progress_vs_plan | P4: sav_litigation | Q4: macro_sensitivity | R4: land_cost_ratio | S4: authorization_completeness_pct | T4: regional_market_tension | U4: contractor_quality | V4: equipment_unbudgeted_pct | W4: tranche_dependency | X4: pre_sale_rate | Y4: sales_vs_plan | Z4: dso_days | AA4: cash_coverage | AB4: funding_gap_pct | AC4: stock_rotation_months | AD4: stressed_margin_pct | AE4: secured_sales_rate | AF4: slow_liquidity_share_pct | AG4: cancellation_rate_pct | AH4: gross_margin_pct | AI4: ltc | AJ4: ltv_stressed | AK4: guarantee_coverage | AL4: first_rank | AM4: interest_coverage | AN4: release_quotity_gap_pts | AO4: drawdown_vs_progress_pct | AP4: cost_overrun_pct | AQ4: dpd_days | AR4: construction_delay_months | AS4: project_stopped_months | AT4: restructured | AU4: legal_exposure | AV4: equity_negative | AW4: funding_gap_persistent | AX4: works_authorization_blocked | AY4: buyers_financing_at_risk | AZ4: release_underpriced | BA4: division_limit_breach | BB4: drawdown_ahead_of_works | BC4: drawdown_schedule_late | BD4: equipment_delivery_at_risk | BE4: component_exit_unsecured | BF4: Score final | BG4: Décision | BH4: Classe interne | BI4: Malus D5 | BJ4: Dossier complet | BK4: D1 | BL4: D2 | BM4: D3 | BN4: D4 | BO4: Score éco. | BP4: Note sûretés | BQ4: PD indicative | BR4: Alertes | BS4: Données manquantes | BT4: Conditions
A5: EXEMPLE-1 | B5: Dossier solide, classe saine | E5: SAIN | F5: 8 | G5: 85 | H5: claire | I5: 35 | J5: structure | K5: 100 | L5: definitives | M5: aligne | N5: standard | O5: 100 | P5: faible | Q5: faible | R5: 22 | S5: 100 | T5: porteur | U5: qualifiee_garantie | V5: 0 | W5: programme_entier | X5: 62 | Y5: 100 | Z5: 90 | AA5: 1.35 | AB5: 0 | AC5: 16 | AD5: 18 | AE5: 55 | AF5: 5 | AG5: 3 | AH5: 27 | AI5: 61 | AJ5: 65 | AK5: 125 | AL5: oui | AM5: 3.2 | AN5: 5 | AO5: 98 | AP5: 2 | AQ5: 0 | AR5: 0 | AS5: 0 | AT5: no | AU5: clear | AV5: Non | AW5: Non | AX5: Non | AY5: Non | AZ5: Non | BA5: Non | BB5: Non | BC5: Non | BD5: Non | BE5: Non
A6: EXEMPLE-2 | B6: Dossier intermédiaire (score moyen) | C6: intermediaire | D6: casa_peripherie | E6: SAIN | F6: 2 | G6: 120 | H6: partielle | I6: 50 | J6: regional | K6: 90 | L6: partielles | M6: moyen | N6: moyenne | O6: 90 | P6: moyen | Q6: moyenne | R6: 30 | S6: 70 | T6: equilibre | U6: qualifiee | V6: 1.5 | W6: dependante_financee | X6: 35 | Y6: 90 | Z6: 180 | AA6: 1.1 | AB6: 5 | AC6: 24 | AD6: 12 | AE6: 30 | AF6: 25 | AG6: 12 | AH6: 20 | AI6: 70 | AJ6: 78 | AK6: 100 | AL6: oui | AM6: 2 | AN6: -5 | AO6: 108 | AP6: 7 | AQ6: 0 | AR6: 0 | AS6: 0 | AT6: no | AU6: clear | AV6: Non | AW6: Non | AX6: Non | AY6: Non | AZ6: Non | BA6: Non | BB6: Non | BC6: Non | BD6: Non | BE6: Non
A7: EXEMPLE-3 | B7: Non 1er rang + restructuration : malus cumulés | E7: SAIN | F7: 8 | G7: 85 | H7: claire | I7: 35 | J7: structure | K7: 100 | L7: definitives | M7: aligne | N7: standard | O7: 100 | P7: faible | Q7: faible | R7: 22 | S7: 100 | T7: porteur | U7: qualifiee_garantie | V7: 0 | W7: programme_entier | X7: 62 | Y7: 100 | Z7: 90 | AA7: 1.35 | AB7: 0 | AC7: 16 | AD7: 18 | AE7: 55 | AF7: 5 | AG7: 3 | AH7: 27 | AI7: 61 | AJ7: 65 | AK7: 125 | AL7: non | AM7: 3.2 | AN7: 5 | AO7: 98 | AP7: 2 | AQ7: 0 | AR7: 0 | AS7: 0 | AT7: yes | AU7: clear | AV7: Non | AW7: Non | AX7: Non | AY7: Non | AZ7: Non | BA7: Non | BB7: Non | BC7: Non | BD7: Non | BE7: Non

Sheet Stress
A1: Stress test sur le dossier courant (onglet Saisie)
A2: Chocs appliqués aux données primitives par identités comptables (marge, LTV, LTC) — mêmes règles que l'application. Macro : LancerStress.
A3: Score de base | D3: Décision de base
A4: Scénario | B4: Libellé | C4: Prix −% | D4: Coût +% | E4: Retard (mois) | F4: Ventes −% | G4: Taux +bps | H4: Préventes −pts | I4: Retard paiement +j | J4: Score final | K4: Décision | L4: Δ vs base
A5: price10 | B5: Prix −10 % | C5: 10 | D5: 0 | E5: 0 | F5: 0 | G5: 0 | H5: 0 | I5: 0
A6: price15 | B6: Prix −15 % | C6: 15 | D6: 0 | E6: 0 | F6: 0 | G6: 0 | H6: 0 | I6: 0
A7: cost10 | B7: Coût +10 % | C7: 0 | D7: 10 | E7: 0 | F7: 0 | G7: 0 | H7: 0 | I7: 0
A8: delay6 | B8: Retard +6 mois | C8: 0 | D8: 0 | E8: 6 | F8: 0 | G8: 0 | H8: 0 | I8: 0
A9: sales20 | B9: Ventes −20 % | C9: 0 | D9: 0 | E9: 0 | F9: 20 | G9: 0 | H9: 0 | I9: 0
A10: rate200 | B10: Taux +200 bps | C10: 0 | D10: 0 | E10: 0 | F10: 0 | G10: 200 | H10: 0 | I10: 0
A11: severe | B11: Sévère combiné | C11: 15 | D11: 10 | E11: 6 | F11: 20 | G11: 200 | H11: 0 | I11: 0

Sheet Resultat
A1: Résultat du scoring
A2: ="Modèle "&P_Version&" — "&Saisie!C4&" "&Saisie!C5 -> Modèle v5.0.0 — EXEMPLE Dossier d'exemple — à remplacer (ruban « Scoring PI » › Nouveau dossier)
A3: Calcul pas à pas (lecture seule). La synthèse lisible est dans l'onglet Fiche.
E5: (interne) | F5: Challengers (indicatifs — score officiel inchangé)
A6: Score final (0–100) | C6: =IF(E28,0,ROUND(MIN(100,MAX(0,C13*C14)),2)) -> 68.46 | F6: Phase du projet | H6: =IF(Saisie!C9="","(non renseignée)",Saisie!C9) -> CONSTRUCTION
A7: Décision | C7: =IF(E28,"NO_GO",IF(E21,"NO_GO",IF(E22,"NO_GO",IF(E23,"DOSSIER_INCOMPLET",IF(E20,"NO_GO",IF(C6>=P_GO,"GO",IF(C6>=P_GWC,"GO_WITH_CONDITIONS",IF(C6>=P_WATCH,"WATCH_LIST","NO_GO")))))))) -> GO_WITH_CONDITIONS | F7: Score éco. avec pondération de phase | H7: =IF(Saisie!C9="","",IF(SUM(F32:F39)=0,"",ROUND(SUM(G32:G39)/SUM(F32:F39),2))) -> 94.3
A8: Classe interne | C8: =IF(E28,"Souffrance",IF(E21,"Souffrance",IF(E22,"Défaut avéré",IF(E23,"Dossier incomplet",IF(C6>=P_GO,"Sain",IF(C6>=P_GWC,"Surveillance",IF(C6>=P_WATCH,"Sensible probable","Sensible"))))))) -> Surveillance | F8: Écart vs score éco. officiel | H8: =IF(H7="","",ROUND(H7-C10,2)) -> 0.84
A9: PD proxy (indicative, non calibrée) | C9: =IF(E23,"n/d",ROUND(1/(1+EXP(-(P_PDa-P_PDb*C6))),4)) -> 0.0367 | F9: Score ajusté sans coefficients territoriaux | H9: =ROUND(MIN(100,MAX(0,C10)),2) -> 93.46
A10: Score économique S_éco (avant ajustement) | C10: =IF(SUM(D32:D39)=0,0,ROUND(SUM(E32:E39)/SUM(D32:D39),2)) -> 93.46 | F10: Effet des coefficients segment / zone | H10: =ROUND(C11-H9,2) -> 0
A11: Score ajusté S_adj = S_éco×(1+α+β) | C11: =ROUND(MIN(100,MAX(0,C10*(1+C17+C18))),2) -> 93.46
A12: Malus cumulés D5 (points) | C12: =SUM(J108:J137) -> 25
A13: Score après pénalités | C13: =ROUND(MIN(100,MAX(0,C11-C12)),2) -> 68.46
A14: Coefficient réglementaire BAM | C14: =IF(Saisie!C8="",1,IFERROR(VLOOKUP(Saisie!C8,P_Classes,5,FALSE),1)) -> 1
A15: Note économique (capacité de remboursement) | C15: =IFERROR(ROUND(SUMPRODUCT($Q$44:$Q$103*($N$44:$N$103<>"GUARANTEE")*$F$44:$F$103)/SUMPRODUCT($Q$44:$Q$103*($N$44:$N$103<>"GUARANTEE"))/P_Scale*100,2),C10) -> 92.47
A16: Note de sûretés (perte en cas de défaut) | C16: =IFERROR(ROUND(SUMPRODUCT($Q$44:$Q$103*($N$44:$N$103="GUARANTEE")*$F$44:$F$103)/SUMPRODUCT($Q$44:$Q$103*($N$44:$N$103="GUARANTEE"))/P_Scale*100,2),"n/a") -> 100
A17: α segment | C17: =IF(Saisie!$D$6="",0,IFERROR(VLOOKUP(Saisie!$D$6,P_SegTbl,3,FALSE),0)) -> 0
A18: β zone | C18: =IF(Saisie!$D$7="",0,IFERROR(VLOOKUP(Saisie!$D$7,P_ZoneTbl,3,FALSE),0)) -> 0
A19: Segment / zone hors référentiel | C19: =IF(E19,"Oui — à signaler","Non") -> Non | E19: =OR(AND(Saisie!$D$6<>"",ISNA(MATCH(Saisie!$D$6,P_SegCodes,0))),AND(Saisie!$D$7<>"",ISNA(MATCH(Saisie!$D$7,P_ZoneCodes,0)))) -> FALSE
A20: Critère éliminatoire (gate) franchi | C20: =IF(E20,"Oui","Non") -> Non | E20: =OR(I44:I103) -> FALSE
A21: Alerte bloquante (souffrance automatique) | C21: =IF(E21,"Oui","Non") -> Non | E21: =SUMPRODUCT((C108:C137="BLOCKING")*(H108:H137=TRUE))>0 -> FALSE
A22: Défaut avéré (classe réglementaire) | C22: =IF(E22,"Oui","Non") -> Non | E22: =OR(IFERROR(VLOOKUP(Saisie!C8,P_Classes,3,FALSE)="Oui",FALSE),Saisie!C8="CTX") -> FALSE
A23: Dossier incomplet (donnée décisionnelle absente) | C23: =IF(E23,"Oui","Non") -> Non | E23: =OR(Saisie!C8="",J43,SUMPRODUCT((J44:J103=TRUE)*1)>0,SUMPRODUCT((L108:L137=TRUE)*1)>0) -> FALSE
A24: Données décisionnelles manquantes | C24: =IF(C6=C6,O137,"")
A25: Conditions (critères éliminatoires franchis) | C25: =S103
A26: Alertes déclenchées / non exclues | C26: =N137 -> RF_CASH_LT_ECH
A27: Retour en comité requis | C27: =IF(E27,"Oui","Non") -> Non | E27: =OR(K108:K137) -> FALSE
A28: Classe bloquante (contentieux) | C28: =IF(E28,"Oui","Non") -> Non | E28: =OR(IFERROR(VLOOKUP(Saisie!C8,P_Classes,4,FALSE)="Oui",FALSE),Saisie!C8="CTX") -> FALSE
A30: Scores par domaine
A31: Code | B31: Domaine | C31: Score /100 | D31: Poids | E31: Contribution | F31: Poids phase | G31: Contribution phase
A32: =IF(P_General!A16="","",P_General!A16) -> D1 | B32: =IF($A32="","",P_General!B16) -> Sponsor & Gouvernance | C32: =IF($A32="",0,IF(SUMIF($B$44:$B$103,$A32,$G$44:$G$103)>0,ROUND(SUMIF($B$44:$B$103,$A32,$H$44:$H$103)/SUMIF($B$44:$B$103,$A32,$G$44:$G$103)/P_Scale*100,2),0)) -> 100 | D32: =IF($A32="",0,P_General!C16) -> 0.25 | E32: =IF($A32="",0,ROUND(C32*D32,2)) -> 25 | F32: =IF($A32="",0,IFERROR(INDEX(P_PhaseTbl,MATCH(Saisie!$C$9,P_PhaseCodes,0),MATCH($A32,P_PhaseHdr,0)+1),0)) -> 0.2 | G32: =ROUND(C32*F32,2) -> 20
A33: =IF(P_General!A17="","",P_General!A17) -> D2 | B33: =IF($A33="","",P_General!B17) -> Qualité intrinsèque du projet | C33: =IF($A33="",0,IF(SUMIF($B$44:$B$103,$A33,$G$44:$G$103)>0,ROUND(SUMIF($B$44:$B$103,$A33,$H$44:$H$103)/SUMIF($B$44:$B$103,$A33,$G$44:$G$103)/P_Scale*100,2),0)) -> 100 | D33: =IF($A33="",0,P_General!C17) -> 0.2 | E33: =IF($A33="",0,ROUND(C33*D33,2)) -> 20 | F33: =IF($A33="",0,IFERROR(INDEX(P_PhaseTbl,MATCH(Saisie!$C$9,P_PhaseCodes,0),MATCH($A33,P_PhaseHdr,0)+1),0)) -> 0.25 | G33: =ROUND(C33*F33,2) -> 25
A34: =IF(P_General!A18="","",P_General!A18) -> D3 | B34: =IF($A34="","",P_General!B18) -> Commercial & Cash-flow | C34: =IF($A34="",0,IF(SUMIF($B$44:$B$103,$A34,$G$44:$G$103)>0,ROUND(SUMIF($B$44:$B$103,$A34,$H$44:$H$103)/SUMIF($B$44:$B$103,$A34,$G$44:$G$103)/P_Scale*100,2),0)) -> 82 | D34: =IF($A34="",0,P_General!C18) -> 0.31 | E34: =IF($A34="",0,ROUND(C34*D34,2)) -> 25.42 | F34: =IF($A34="",0,IFERROR(INDEX(P_PhaseTbl,MATCH(Saisie!$C$9,P_PhaseCodes,0),MATCH($A34,P_PhaseHdr,0)+1),0)) -> 0.25 | G34: =ROUND(C34*F34,2) -> 20.5
A35: =IF(P_General!A19="","",P_General!A19) -> D4 | B35: =IF($A35="","",P_General!B19) -> Structuration financière & LGD | C35: =IF($A35="",0,IF(SUMIF($B$44:$B$103,$A35,$G$44:$G$103)>0,ROUND(SUMIF($B$44:$B$103,$A35,$H$44:$H$103)/SUMIF($B$44:$B$103,$A35,$G$44:$G$103)/P_Scale*100,2),0)) -> 96 | D35: =IF($A35="",0,P_General!C19) -> 0.24 | E35: =IF($A35="",0,ROUND(C35*D35,2)) -> 23.04 | F35: =IF($A35="",0,IFERROR(INDEX(P_PhaseTbl,MATCH(Saisie!$C$9,P_PhaseCodes,0),MATCH($A35,P_PhaseHdr,0)+1),0)) -> 0.3 | G35: =ROUND(C35*F35,2) -> 28.8
A36: =IF(P_General!A20="","",P_General!A20) | B36: =IF($A36="","",P_General!B20) | C36: =IF($A36="",0,IF(SUMIF($B$44:$B$103,$A36,$G$44:$G$103)>0,ROUND(SUMIF($B$44:$B$103,$A36,$H$44:$H$103)/SUMIF($B$44:$B$103,$A36,$G$44:$G$103)/P_Scale*100,2),0)) -> 0 | D36: =IF($A36="",0,P_General!C20) -> 0 | E36: =IF($A36="",0,ROUND(C36*D36,2)) -> 0 | F36: =IF($A36="",0,IFERROR(INDEX(P_PhaseTbl,MATCH(Saisie!$C$9,P_PhaseCodes,0),MATCH($A36,P_PhaseHdr,0)+1),0)) -> 0 | G36: =ROUND(C36*F36,2) -> 0
A37: =IF(P_General!A21="","",P_General!A21) | B37: =IF($A37="","",P_General!B21) | C37: =IF($A37="",0,IF(SUMIF($B$44:$B$103,$A37,$G$44:$G$103)>0,ROUND(SUMIF($B$44:$B$103,$A37,$H$44:$H$103)/SUMIF($B$44:$B$103,$A37,$G$44:$G$103)/P_Scale*100,2),0)) -> 0 | D37: =IF($A37="",0,P_General!C21) -> 0 | E37: =IF($A37="",0,ROUND(C37*D37,2)) -> 0 | F37: =IF($A37="",0,IFERROR(INDEX(P_PhaseTbl,MATCH(Saisie!$C$9,P_PhaseCodes,0),MATCH($A37,P_PhaseHdr,0)+1),0)) -> 0 | G37: =ROUND(C37*F37,2) -> 0
A38: =IF(P_General!A22="","",P_General!A22) | B38: =IF($A38="","",P_General!B22) | C38: =IF($A38="",0,IF(SUMIF($B$44:$B$103,$A38,$G$44:$G$103)>0,ROUND(SUMIF($B$44:$B$103,$A38,$H$44:$H$103)/SUMIF($B$44:$B$103,$A38,$G$44:$G$103)/P_Scale*100,2),0)) -> 0 | D38: =IF($A38="",0,P_General!C22) -> 0 | E38: =IF($A38="",0,ROUND(C38*D38,2)) -> 0 | F38: =IF($A38="",0,IFERROR(INDEX(P_PhaseTbl,MATCH(Saisie!$C$9,P_PhaseCodes,0),MATCH($A38,P_PhaseHdr,0)+1),0)) -> 0 | G38: =ROUND(C38*F38,2) -> 0
A39: =IF(P_General!A23="","",P_General!A23) | B39: =IF($A39="","",P_General!B23) | C39: =IF($A39="",0,IF(SUMIF($B$44:$B$103,$A39,$G$44:$G$103)>0,ROUND(SUMIF($B$44:$B$103,$A39,$H$44:$H$103)/SUMIF($B$44:$B$103,$A39,$G$44:$G$103)/P_Scale*100,2),0)) -> 0 | D39: =IF($A39="",0,P_General!C23) -> 0 | E39: =IF($A39="",0,ROUND(C39*D39,2)) -> 0 | F39: =IF($A39="",0,IFERROR(INDEX(P_PhaseTbl,MATCH(Saisie!$C$9,P_PhaseCodes,0),MATCH($A39,P_PhaseHdr,0)+1),0)) -> 0 | G39: =ROUND(C39*F39,2) -> 0
A41: Détail par critère (explicabilité)
A42: Code | B42: Domaine | C42: Critère | D42: Clé | E42: Valeur | F42: Note /10 | G42: Poids | H42: Pondéré | I42: Gate franchi | J42: Donnée critique manquante | K42: Note plancher | L42: Nb correspondances | M42: Note brute | N42: Famille | O42: Type | P42: Poids domaine | Q42: Poids effectif | R42: Cumul manquantes | S42: Cumul conditions | T42: Libellés manquants | U42: Rang (lecture) | V42: Valeur en clair
A43: (clé additionnelle) | D43: =P_ExtraKey -> dpd_days | E43: =IF(D43="","",IFERROR(INDEX(In_Retenue,MATCH(D43,In_Cles,0)),"")) -> 0 | J43: =AND(D43<>"",E43="") -> FALSE | R43: =IF(J43,D43,"") | S43: ="" | T43: =IF(J43,IFERROR(INDEX(Saisie!$C$13:$C$92,MATCH(D43,In_Cles,0)),D43),"")
...

Sheet Historique
A1: Historique des calculs (journal)
A2: Alimenté par les macros (ScorerDossier, ScorerPortefeuille). La version du modèle est tracée sur chaque ligne.
A4: Date / heure | B4: Utilisateur | C4: Dossier | D4: Version du modèle | E4: Score final | F4: Décision | G4: Classe interne | H4: Malus D5 | I4: Dossier complet

Sheet Aide
B1: Aide — outil de scoring de la promotion immobilière
B2: ="Modèle PI_PROMOTION "&P_Version&" — publié le "&P_Date&" · outil 5.1 (05/10/2026)" -> Modèle PI_PROMOTION v5.0.0 — publié le 2026-10-01 · outil 5.1 (05/10/2026)
B4: À quoi sert ce classeur | C4: Calculer le score, la décision et la classe interne d'un dossier de promotion immobilière selon le modèle publié, hors de l'application : simulation, préparation de comité, agence, dépannage, formation. Il reproduit le moteur de production (vérifié sur 26 cas de référence).
B5: Principe | C5: Le MOTEUR est en formules Excel (onglet Resultat) : chaque note est traçable cellule par cellule et les barèmes se modifient sans code. Les macros AUTOMATISENT : nouveau dossier, enregistrer / ouvrir un dossier, export PDF, stress test, scoring de portefeuille, autotests, validation du modèle, journal.
B6: Parcours | C6: Accueil → Saisie (cellules jaunes, résultat en direct) → Fiche (synthèse imprimable). Calculateurs, Portefeuille, Stress et Historique au besoin. Resultat = calcul pas à pas.
B7: Ruban « Scoring PI » | C7: Dossier : Nouveau, Enregistrer, Ouvrir, Exporter la fiche en PDF. Analyse : Stress test, Scorer le portefeuille. Outil : Autotests, Valider le modèle, Paramètres (afficher / masquer), Aide. Sans ruban : Alt+F8 et choisir la macro (NouveauDossier, EnregistrerDossier, OuvrirDossier, ExporterPDF, LancerStress, ScorerPortefeuille, ExecuterAutotests, ValiderModele, BasculerParametres).
B8: Fichier sans macros | C8: Le fichier .xlsx calcule tout (saisie, fiche, résultat). Pour y ajouter les macros : Alt+F11 › Fichier › Importer les 6 fichiers .bas du dossier « vba », puis enregistrer au format .xlsm ; InstallerBoutons ajoute des boutons sur l'Accueil.
B9: Saisie | C9: Vide = donnée absente (jamais 0, jamais « Non »). Pourcentages en points (62 pour 62 %). Listes en clair : le code technique est déduit automatiquement. La colonne « État » indique : ✔ renseigné, ⚠ manquant — décisionnel (le dossier sera incomplet), ○ non renseigné (note plancher), ⚠ valeur à vérifier.
B10: Enregistrer les dossiers | C10: Enregistrer le dossier range les valeurs utilisées (y compris celles des calculateurs) dans le Portefeuille, avec le résultat. Ouvrir un dossier : sélectionnez sa ligne dans le Portefeuille (ou tapez sa référence) ; la saisie et les calculateurs du dossier courant sont d'abord vidés.
B11: Vérifier | C11: Ruban › Autotests : attendu « 26 / 26 cas conformes ». Valider le modèle après toute modification des paramètres.
B12: Invariants de décision | C12: Donnée manquante ≠ amélioration (note plancher ; alerte « non exclue » si sa donnée numérique manque) · Défaut avéré → NO_GO · Classe non renseignée → dossier incomplet · Aucun malus pour la division des risques (retour en comité).
B13: Ce que le classeur ne fait pas | C13: Classification BAM complète (déclencheurs qualitatifs 1/W, restructuration, effet de groupe) : la classe est saisie ; seule une suggestion fondée sur le retard est affichée. Trésorerie mensuelle, LGD, IFRS 9, workflow d'approbation, historisation multi-utilisateurs : dans l'application.
B14: Limites d'usage | C14: Classeur individuel : pas de contrôle d'accès ni de piste d'audit opposable. La décision officielle se prend dans l'application. La PD affichée est INDICATIVE et non calibrée (non affichée si le dossier est incomplet). Les grilles par phase et l'effet des coefficients territoriaux sont des challengers.
