Workbook
Name In_Calc: Saisie!$F$13:$F$92
Name In_Cles: Saisie!$B$13:$B$92
Name In_Retenue: Saisie!$G$13:$G$92
Name In_Saisie: Saisie!$E$13:$E$92
Name P_Classes: P_General!$A$27:$E$36
Name P_ClsCodes: P_General!$A$27:$A$36
Name P_Date: P_General!$B$5
Name P_DomCodes: P_General!$A$16:$A$23
Name P_DomNoms: P_General!$B$16:$B$23
Name P_DomPoids: P_General!$C$16:$C$23
Name P_DPD1: P_General!$B$45
Name P_DPD2: P_General!$B$46
Name P_DPD3: P_General!$B$47
Name P_ExtraKey: P_General!$B$12
Name P_GO: P_General!$B$7
Name P_GWC: P_General!$B$8
Name P_PDa: P_General!$B$10
Name P_PDb: P_General!$B$11
Name P_PhaseCodes: P_General!$A$40:$A$42
Name P_PhaseHdr: P_General!$B$39:$I$39
Name P_PhaseTbl: P_General!$A$40:$I$42
Name P_Scale: P_General!$B$6
Name P_SegCodes: P_Ajustements!$A$5:$A$24
Name P_SegTbl: P_Ajustements!$A$5:$C$24
Name P_Version: P_General!$B$4
Name P_WATCH: P_General!$B$9
Name P_ZoneCodes: P_Ajustements!$E$5:$E$24
Name P_ZoneTbl: P_Ajustements!$E$5:$G$24
Name R_AuthCodes: P_Referentiels!$A$6:$A$29
Name R_AuthTbl: P_Referentiels!$A$6:$I$29
Name R_FinCodes: P_Referentiels!$A$34:$A$45
Name R_FinTbl: P_Referentiels!$A$34:$C$45
Name Res_Adj: Resultat!$C$11
Name Res_Alertes: Resultat!$C$26
Name Res_ClasseInt: Resultat!$C$8
Name Res_Comite: Resultat!$E$27
Name Res_Decision: Resultat!$C$7
Name Res_DomCodes: Resultat!$A$32:$A$39
Name Res_DomScores: Resultat!$C$32:$C$39
Name Res_EcoScore: Resultat!$C$15
Name Res_GuarScore: Resultat!$C$16
Name Res_Incomplet: Resultat!$E$23
Name Res_Malus: Resultat!$C$12
Name Res_Manquantes: Resultat!$C$24
Name Res_PD: Resultat!$C$9
Name Res_ScoreEco: Resultat!$C$10
Name Res_ScoreFinal: Resultat!$C$6

Sheet LisezMoi
B1: Outil de scoring — Promotion immobilière
B2: ="Modèle PI_PROMOTION "&P_Version&" — publié le "&P_Date -> 0
B4: À quoi sert ce classeur | C4: Calculer le score, la décision et la classe interne d'un dossier de promotion immobilière selon le modèle PI_PROMOTION v4.0.0, hors de l'application : simulation, comité, agence, dépannage. Il reproduit le moteur de production (vérifié sur 20 cas de référence).
B5: Principe | C5: Le MOTEUR est en formules Excel (onglet Resultat) : chaque note est traçable cellule par cellule et les barèmes se modifient sans code. Le VBA (fichiers .bas fournis) AUTOMATISE : scoring de portefeuille, stress test, validation du modèle, autotests, journal, export PDF.
B6: 1. Renseigner un dossier | C6: Onglet Saisie : segment, zone, classe réglementaire BAM, puis les données (cellules jaunes). Les données dérivées (autorisations, ventes sécurisées, mainlevée, division des risques) peuvent être calculées dans l'onglet Calculateurs ; une valeur saisie prime.
B7: 2. Lire le résultat | C7: Onglet Resultat : score final, décision, classe interne, malus, alertes, détail par critère et par domaine. Une donnée décisionnelle absente donne « DOSSIER_INCOMPLET » — jamais un meilleur score.
B8: 3. Automatiser (VBA) | C8: Alt+F11 → Fichier → Importer un fichier → sélectionner les 5 fichiers .bas du dossier « vba ». Puis exécuter InstallerBoutons (une seule fois) et enregistrer le classeur au format .xlsm.
B9: 4. Vérifier | C9: Exécuter ExecuterAutotests : compare les résultats du classeur à 20 cas de référence issus du moteur de production. Exécuter ValiderModele après toute modification des paramètres.
B10: Invariants de décision | C10: Donnée manquante ≠ amélioration (note plancher ; alerte « non exclue » si sa donnée numérique manque) · Défaut avéré → NO_GO · Classe non renseignée → dossier incomplet · Aucun malus pour la division des risques (retour en comité).
B11: Ce que le classeur ne fait pas | C11: Classification BAM complète (déclencheurs qualitatifs 1/W, restructuration, effet de groupe) : la classe est saisie ; seule une suggestion fondée sur le retard est affichée. Trésorerie mensuelle, LGD, IFRS 9, workflow d'approbation, historisation multi-utilisateurs : dans l'application.
B12: Limites d'usage | C12: Classeur individuel : pas de contrôle d'accès ni de piste d'audit opposable. La PD affichée est INDICATIVE et non calibrée : ne pas l'utiliser pour des pertes attendues ou du capital. Les grilles par phase et l'effet des coefficients territoriaux sont des challengers, pas la décision.
B13: Paramétrage | C13: Onglets P_* (bleus) : critères, barèmes, alertes, ajustements, référentiels, seuils. Modifier = ValiderModele + nouvelle version (macro SnapshotModele) + information du propriétaire du modèle. La version de référence reste celle de l'application.
B14: Compatibilité | C14: Excel 2010 ou plus récent (Windows), Excel pour Mac pour les formules. Les macros n'utilisent pas de bibliothèque externe. Aucun contenu actif n'est intégré au fichier .xlsx fourni.
B16: Onglets
B17: Saisie | C17: Données du dossier
B18: Resultat | C18: Moteur de calcul et restitution
B19: Calculateurs | C19: Autorisations, ventes sécurisées, mainlevée, division des risques
B20: Portefeuille | C20: Scoring de masse (macro)
B21: Stress | C21: Chocs sur le dossier courant (macro)
B22: Tests | C22: 20 cas de référence (macro)
B23: Historique | C23: Journal des calculs
B24: P_* | C24: Paramètres du modèle (bleus)

Sheet Saisie
A1: Saisie du dossier
A2: Cellules jaunes = à renseigner. Une donnée absente n'améliore JAMAIS le résultat (note plancher, ou « dossier incomplet » si la donnée est décisionnelle).
A4: Référence dossier
A5: Nom du projet
A6: Segment
A7: Zone
A8: Classe réglementaire BAM | E8: =IFERROR(IF(NOT(ISNUMBER(INDEX(In_Retenue,MATCH("dpd_days",In_Cles,0)))),"",IF(INDEX(In_Retenue,MATCH("dpd_days",In_Cles,0))>=P_DPD3,"COMPROMIS",IF(INDEX(In_Retenue,MATCH("dpd_days",In_Cles,0))>=P_DPD2,"DOUTEUX",IF(INDEX(In_Retenue,MATCH("dpd_days",In_Cles,0))>=P_DPD1,"PRE_DOUTEUX","SAIN")))),"") -> 0 | F8: =IF(OR(C8="",E8=""),"",IF(MATCH(C8,P_ClsCodes,0)<MATCH(E8,P_ClsCodes,0),"⚠ Classe moins sévère que le retard constaté","Cohérent avec le retard")) -> 0 | G8: ← classe suggérée par le seul retard de paiement (les déclencheurs qualitatifs 1/W — art. 5, 12.6, 12.7, restructuration — restent à apprécier)
A9: Phase du projet (challenger)
A10: Version du modèle | C10: =P_Version&" — "&P_Date -> 0
A12: Section | B12: Clé technique | C12: Donnée | D12: Type | E12: Valeur saisie | F12: Valeur calculée | G12: Valeur retenue | H12: Aide
A13: D1 — Sponsor & Gouvernance | B13: promoter_completed_projects | C13: Projets similaires livrés (5 ans) | D13: NUM | G13: =IF(E13<>"",IF(D13="BOOL",IF(E13="Oui",TRUE,IF(E13="Non",FALSE,"")),E13),IF(F13="","",IF(D13="BOOL",IF(F13="Oui",TRUE,IF(F13="Non",FALSE,"")),F13))) -> 0 | H13: nombre (ratio/%)
A14: D1 — Sponsor & Gouvernance | B14: promoter_gearing | C14: Gearing promoteur (dettes nettes / FP) | D14: NUM | G14: =IF(E14<>"",IF(D14="BOOL",IF(E14="Oui",TRUE,IF(E14="Non",FALSE,"")),E14),IF(F14="","",IF(D14="BOOL",IF(F14="Oui",TRUE,IF(F14="Non",FALSE,"")),F14))) -> 0 | H14: nombre (ratio/%)
A15: D1 — Sponsor & Gouvernance | B15: governance_quality | C15: Gouvernance & structure juridique | D15: QUAL | G15: =IF(E15<>"",IF(D15="BOOL",IF(E15="Oui",TRUE,IF(E15="Non",FALSE,"")),E15),IF(F15="","",IF(D15="BOOL",IF(F15="Oui",TRUE,IF(F15="Non",FALSE,"")),F15))) -> 0 | H15: valeurs : opaque | partielle | claire
A16: D1 — Sponsor & Gouvernance | B16: mono_project_concentration | C16: Concentration mono-projet (CA projet / CA total) | D16: NUM | G16: =IF(E16<>"",IF(D16="BOOL",IF(E16="Oui",TRUE,IF(E16="Non",FALSE,"")),E16),IF(F16="","",IF(D16="BOOL",IF(F16="Oui",TRUE,IF(F16="Non",FALSE,"")),F16))) -> 0 | H16: nombre (ratio/%)
A17: D1 — Sponsor & Gouvernance | B17: promoter_type | C17: Typologie promoteur | D17: QUAL | G17: =IF(E17<>"",IF(D17="BOOL",IF(E17="Oui",TRUE,IF(E17="Non",FALSE,"")),E17),IF(F17="","",IF(D17="BOOL",IF(F17="Oui",TRUE,IF(F17="Non",FALSE,"")),F17))) -> 0 | H17: valeurs : opportuniste | regional | structure
A18: D1 — Sponsor & Gouvernance | B18: equity_injected_ratio | C18: Apport effectif (injecté / prévu) | D18: NUM | G18: =IF(E18<>"",IF(D18="BOOL",IF(E18="Oui",TRUE,IF(E18="Non",FALSE,"")),E18),IF(F18="","",IF(D18="BOOL",IF(F18="Oui",TRUE,IF(F18="Non",FALSE,"")),F18))) -> 0 | H18: nombre (ratio/%)
A19: D2 — Qualité intrinsèque du projet | B19: land_permits_status | C19: Foncier & autorisations | D19: QUAL | G19: =IF(E19<>"",IF(D19="BOOL",IF(E19="Oui",TRUE,IF(E19="Non",FALSE,"")),E19),IF(F19="","",IF(D19="BOOL",IF(F19="Oui",TRUE,IF(F19="Non",FALSE,"")),F19))) -> 0 | H19: valeurs : absentes | partielles | definitives
A20: D2 — Qualité intrinsèque du projet | B20: market_positioning | C20: Marché & positionnement | D20: QUAL | G20: =IF(E20<>"",IF(D20="BOOL",IF(E20="Oui",TRUE,IF(E20="Non",FALSE,"")),E20),IF(F20="","",IF(D20="BOOL",IF(F20="Oui",TRUE,IF(F20="Non",FALSE,"")),F20))) -> 0 | H20: valeurs : sur_positionne | moyen | aligne
A21: D2 — Qualité intrinsèque du projet | B21: technical_complexity | C21: Complexité technique | D21: QUAL | G21: =IF(E21<>"",IF(D21="BOOL",IF(E21="Oui",TRUE,IF(E21="Non",FALSE,"")),E21),IF(F21="","",IF(D21="BOOL",IF(F21="Oui",TRUE,IF(F21="Non",FALSE,"")),F21))) -> 0 | H21: valeurs : elevee | moyenne | standard
A22: D2 — Qualité intrinsèque du projet | B22: progress_vs_plan | C22: Avancement vs planning | D22: NUM | G22: =IF(E22<>"",IF(D22="BOOL",IF(E22="Oui",TRUE,IF(E22="Non",FALSE,"")),E22),IF(F22="","",IF(D22="BOOL",IF(F22="Oui",TRUE,IF(F22="Non",FALSE,"")),F22))) -> 0 | H22: nombre (ratio/%)
A23: D2 — Qualité intrinsèque du projet | B23: sav_litigation | C23: Litiges clients / SAV | D23: QUAL | G23: =IF(E23<>"",IF(D23="BOOL",IF(E23="Oui",TRUE,IF(E23="Non",FALSE,"")),E23),IF(F23="","",IF(D23="BOOL",IF(F23="Oui",TRUE,IF(F23="Non",FALSE,"")),F23))) -> 0 | H23: valeurs : eleve | moyen | faible
A24: D2 — Qualité intrinsèque du projet | B24: macro_sensitivity | C24: Sensibilité macro / subvention | D24: QUAL | G24: =IF(E24<>"",IF(D24="BOOL",IF(E24="Oui",TRUE,IF(E24="Non",FALSE,"")),E24),IF(F24="","",IF(D24="BOOL",IF(F24="Oui",TRUE,IF(F24="Non",FALSE,"")),F24))) -> 0 | H24: valeurs : elevee | moyenne | faible
A25: D2 — Qualité intrinsèque du projet | B25: land_cost_ratio | C25: Coût foncier / CA | D25: NUM | G25: =IF(E25<>"",IF(D25="BOOL",IF(E25="Oui",TRUE,IF(E25="Non",FALSE,"")),E25),IF(F25="","",IF(D25="BOOL",IF(F25="Oui",TRUE,IF(F25="Non",FALSE,"")),F25))) -> 0 | H25: nombre (ratio/%)
A26: D2 — Qualité intrinsèque du projet | B26: authorization_completeness_pct | C26: Chaîne d'autorisations (complétude) | D26: NUM | F26: =IF(Calculateurs!C35,Calculateurs!C33,"") -> 0 | G26: =IF(E26<>"",IF(D26="BOOL",IF(E26="Oui",TRUE,IF(E26="Non",FALSE,"")),E26),IF(F26="","",IF(D26="BOOL",IF(F26="Oui",TRUE,IF(F26="Non",FALSE,"")),F26))) -> 0 | H26: nombre (%) — calculé par l'onglet Calculateurs ; la saisie prime
A27: D3 — Commercial & Cash-flow | B27: pre_sale_rate | C27: Préventes sécurisées (encaissées / CA) | D27: NUM | G27: =IF(E27<>"",IF(D27="BOOL",IF(E27="Oui",TRUE,IF(E27="Non",FALSE,"")),E27),IF(F27="","",IF(D27="BOOL",IF(F27="Oui",TRUE,IF(F27="Non",FALSE,"")),F27))) -> 0 | H27: nombre (ratio/%)
A28: D3 — Commercial & Cash-flow | B28: sales_vs_plan | C28: Ventes vs planning | D28: NUM | G28: =IF(E28<>"",IF(D28="BOOL",IF(E28="Oui",TRUE,IF(E28="Non",FALSE,"")),E28),IF(F28="","",IF(D28="BOOL",IF(F28="Oui",TRUE,IF(F28="Non",FALSE,"")),F28))) -> 0 | H28: nombre (ratio/%)
A29: D3 — Commercial & Cash-flow | B29: dso_days | C29: DSO (jours) | D29: NUM | G29: =IF(E29<>"",IF(D29="BOOL",IF(E29="Oui",TRUE,IF(E29="Non",FALSE,"")),E29),IF(F29="","",IF(D29="BOOL",IF(F29="Oui",TRUE,IF(F29="Non",FALSE,"")),F29))) -> 0 | H29: nombre (ratio/%)
A30: D3 — Commercial & Cash-flow | B30: cash_coverage | C30: Cash coverage (cash / échéances) | D30: NUM | G30: =IF(E30<>"",IF(D30="BOOL",IF(E30="Oui",TRUE,IF(E30="Non",FALSE,"")),E30),IF(F30="","",IF(D30="BOOL",IF(F30="Oui",TRUE,IF(F30="Non",FALSE,"")),F30))) -> 0 | H30: nombre (ratio/%)
A31: D3 — Commercial & Cash-flow | B31: funding_gap_pct | C31: Impasse brute | D31: NUM | G31: =IF(E31<>"",IF(D31="BOOL",IF(E31="Oui",TRUE,IF(E31="Non",FALSE,"")),E31),IF(F31="","",IF(D31="BOOL",IF(F31="Oui",TRUE,IF(F31="Non",FALSE,"")),F31))) -> 0 | H31: nombre (ratio/%)
A32: D3 — Commercial & Cash-flow | B32: stock_rotation_months | C32: Rotation stock (mois) | D32: NUM | G32: =IF(E32<>"",IF(D32="BOOL",IF(E32="Oui",TRUE,IF(E32="Non",FALSE,"")),E32),IF(F32="","",IF(D32="BOOL",IF(F32="Oui",TRUE,IF(F32="Non",FALSE,"")),F32))) -> 0 | H32: nombre (ratio/%)
A33: D3 — Commercial & Cash-flow | B33: stressed_margin_pct | C33: Marge brute stressée (prix -10%) | D33: NUM | G33: =IF(E33<>"",IF(D33="BOOL",IF(E33="Oui",TRUE,IF(E33="Non",FALSE,"")),E33),IF(F33="","",IF(D33="BOOL",IF(F33="Oui",TRUE,IF(F33="Non",FALSE,"")),F33))) -> 0 | H33: nombre (ratio/%)
A34: D3 — Commercial & Cash-flow | B34: secured_sales_rate | C34: Ventes sécurisées (financement acquéreur) | D34: NUM | F34: =Calculateurs!C85 -> 0 | G34: =IF(E34<>"",IF(D34="BOOL",IF(E34="Oui",TRUE,IF(E34="Non",FALSE,"")),E34),IF(F34="","",IF(D34="BOOL",IF(F34="Oui",TRUE,IF(F34="Non",FALSE,"")),F34))) -> 0 | H34: nombre (%) — calculé par l'onglet Calculateurs ; la saisie prime
A35: D4 — Structuration financière & LGD | B35: gross_margin_pct | C35: Marge brute (CA - coûts directs)/CA | D35: NUM | G35: =IF(E35<>"",IF(D35="BOOL",IF(E35="Oui",TRUE,IF(E35="Non",FALSE,"")),E35),IF(F35="","",IF(D35="BOOL",IF(F35="Oui",TRUE,IF(F35="Non",FALSE,"")),F35))) -> 0 | H35: nombre (ratio/%)
A36: D4 — Structuration financière & LGD | B36: ltc | C36: LTC (dette / coût total) | D36: NUM | G36: =IF(E36<>"",IF(D36="BOOL",IF(E36="Oui",TRUE,IF(E36="Non",FALSE,"")),E36),IF(F36="","",IF(D36="BOOL",IF(F36="Oui",TRUE,IF(F36="Non",FALSE,"")),F36))) -> 0 | H36: nombre (ratio/%)
A37: D4 — Structuration financière & LGD | B37: ltv_stressed | C37: LTV stressée (dette / valeur×0,90) | D37: NUM | G37: =IF(E37<>"",IF(D37="BOOL",IF(E37="Oui",TRUE,IF(E37="Non",FALSE,"")),E37),IF(F37="","",IF(D37="BOOL",IF(F37="Oui",TRUE,IF(F37="Non",FALSE,"")),F37))) -> 0 | H37: nombre (ratio/%)
A38: D4 — Structuration financière & LGD | B38: guarantee_coverage | C38: Couverture garanties réalisable | D38: NUM | G38: =IF(E38<>"",IF(D38="BOOL",IF(E38="Oui",TRUE,IF(E38="Non",FALSE,"")),E38),IF(F38="","",IF(D38="BOOL",IF(F38="Oui",TRUE,IF(F38="Non",FALSE,"")),F38))) -> 0 | H38: nombre (ratio/%)
A39: D4 — Structuration financière & LGD | B39: first_rank | C39: Rang bancaire 1er rang | D39: QUAL | G39: =IF(E39<>"",IF(D39="BOOL",IF(E39="Oui",TRUE,IF(E39="Non",FALSE,"")),E39),IF(F39="","",IF(D39="BOOL",IF(F39="Oui",TRUE,IF(F39="Non",FALSE,"")),F39))) -> 0 | H39: valeurs : non | oui
A40: D4 — Structuration financière & LGD | B40: interest_coverage | C40: Interest coverage (EBITDA / charges fin.) | D40: NUM | G40: =IF(E40<>"",IF(D40="BOOL",IF(E40="Oui",TRUE,IF(E40="Non",FALSE,"")),E40),IF(F40="","",IF(D40="BOOL",IF(F40="Oui",TRUE,IF(F40="Non",FALSE,"")),F40))) -> 0 | H40: nombre (ratio/%)
A41: D4 — Structuration financière & LGD | B41: release_quotity_gap_pts | C41: Quotité de désengagement vs équilibre | D41: NUM | F41: =Calculateurs!C94 -> 0 | G41: =IF(E41<>"",IF(D41="BOOL",IF(E41="Oui",TRUE,IF(E41="Non",FALSE,"")),E41),IF(F41="","",IF(D41="BOOL",IF(F41="Oui",TRUE,IF(F41="Non",FALSE,"")),F41))) -> 0 | H41: nombre (pts) — calculé par l'onglet Calculateurs ; la saisie prime
A42: Alertes D5 | B42: dpd_days | C42: Retard de paiement (jours) | D42: NUM | G42: =IF(E42<>"",IF(D42="BOOL",IF(E42="Oui",TRUE,IF(E42="Non",FALSE,"")),E42),IF(F42="","",IF(D42="BOOL",IF(F42="Oui",TRUE,IF(F42="Non",FALSE,"")),F42))) -> 0 | H42: nombre — donnée décisionnelle
...

Sheet Resultat
A1: Résultat du scoring
A2: ="Modèle "&P_Version&" — "&Saisie!C4&" "&Saisie!C5 -> 0
E5: (interne) | F5: Challengers (indicatifs — score officiel inchangé)
A6: Score final (0–100) | C6: =IF(E28,0,ROUND(MIN(100,MAX(0,C13*C14)),2)) -> 0 | F6: Phase du projet | H6: =IF(Saisie!C9="","(non renseignée)",Saisie!C9) -> 0
A7: Décision | C7: =IF(E28,"NO_GO",IF(E21,"NO_GO",IF(E22,"NO_GO",IF(E23,"DOSSIER_INCOMPLET",IF(E20,"NO_GO",IF(C6>=P_GO,"GO",IF(C6>=P_GWC,"GO_WITH_CONDITIONS",IF(C6>=P_WATCH,"WATCH_LIST","NO_GO")))))))) -> 0 | F7: Score éco. avec pondération de phase | H7: =IF(Saisie!C9="","",IF(SUM(F32:F39)=0,"",ROUND(SUM(G32:G39)/SUM(F32:F39),2))) -> 0
A8: Classe interne | C8: =IF(E28,"Souffrance",IF(E21,"Souffrance",IF(E22,"Défaut avéré",IF(E23,"Dossier incomplet",IF(C6>=P_GO,"Sain",IF(C6>=P_GWC,"Surveillance",IF(C6>=P_WATCH,"Sensible probable","Sensible"))))))) -> 0 | F8: Écart vs score éco. officiel | H8: =IF(H7="","",ROUND(H7-C10,2)) -> 0
A9: PD proxy (indicative, non calibrée) | C9: =ROUND(1/(1+EXP(-(P_PDa-P_PDb*C6))),4) -> 0 | F9: Score ajusté sans coefficients territoriaux | H9: =ROUND(MIN(100,MAX(0,C10)),2) -> 0
A10: Score économique S_éco (avant ajustement) | C10: =IF(SUM(D32:D39)=0,0,ROUND(SUM(E32:E39)/SUM(D32:D39),2)) -> 0 | F10: Effet des coefficients segment / zone | H10: =ROUND(C11-H9,2) -> 0
A11: Score ajusté S_adj = S_éco×(1+α+β) | C11: =ROUND(MIN(100,MAX(0,C10*(1+C17+C18))),2) -> 0
A12: Malus cumulés D5 (points) | C12: =SUM(J108:J137) -> 0
A13: Score après pénalités | C13: =ROUND(MIN(100,MAX(0,C11-C12)),2) -> 0
A14: Coefficient réglementaire BAM | C14: =IF(Saisie!C8="",1,IFERROR(VLOOKUP(Saisie!C8,P_Classes,5,FALSE),1)) -> 0
A15: Note économique (capacité de remboursement) | C15: =IFERROR(ROUND(SUMPRODUCT($Q$44:$Q$103*($N$44:$N$103<>"GUARANTEE")*$F$44:$F$103)/SUMPRODUCT($Q$44:$Q$103*($N$44:$N$103<>"GUARANTEE"))/P_Scale*100,2),C10) -> 0
A16: Note de sûretés (perte en cas de défaut) | C16: =IFERROR(ROUND(SUMPRODUCT($Q$44:$Q$103*($N$44:$N$103="GUARANTEE")*$F$44:$F$103)/SUMPRODUCT($Q$44:$Q$103*($N$44:$N$103="GUARANTEE"))/P_Scale*100,2),"n/a") -> 0
A17: α segment | C17: =IF(Saisie!C6="",0,IFERROR(VLOOKUP(Saisie!C6,P_SegTbl,3,FALSE),0)) -> 0
A18: β zone | C18: =IF(Saisie!C7="",0,IFERROR(VLOOKUP(Saisie!C7,P_ZoneTbl,3,FALSE),0)) -> 0
A19: Segment / zone hors référentiel | C19: =IF(E19,"Oui — à signaler","Non") -> 0 | E19: =OR(AND(Saisie!C6<>"",ISNA(MATCH(Saisie!C6,P_SegCodes,0))),AND(Saisie!C7<>"",ISNA(MATCH(Saisie!C7,P_ZoneCodes,0)))) -> 0
A20: Critère éliminatoire (gate) franchi | C20: =IF(E20,"Oui","Non") -> 0 | E20: =OR(I44:I103) -> 0
A21: Alerte bloquante (souffrance automatique) | C21: =IF(E21,"Oui","Non") -> 0 | E21: =SUMPRODUCT((C108:C137="BLOCKING")*(H108:H137=TRUE))>0 -> 0
A22: Défaut avéré (classe réglementaire) | C22: =IF(E22,"Oui","Non") -> 0 | E22: =OR(IFERROR(VLOOKUP(Saisie!C8,P_Classes,3,FALSE)="Oui",FALSE),Saisie!C8="CTX") -> 0
A23: Dossier incomplet (donnée décisionnelle absente) | C23: =IF(E23,"Oui","Non") -> 0 | E23: =OR(Saisie!C8="",J43,SUMPRODUCT((J44:J103=TRUE)*1)>0,SUMPRODUCT((L108:L137=TRUE)*1)>0) -> 0
A24: Données décisionnelles manquantes | C24: =IF(C6=C6,SUBSTITUTE(M137,",",", "),"") -> 0
A25: Critères éliminatoires franchis | C25: =S103 -> 0
A26: Alertes déclenchées / non exclues | C26: =N137 -> 0
A27: Retour en comité requis | C27: =IF(E27,"Oui","Non") -> 0 | E27: =OR(K108:K137) -> 0
A28: Classe bloquante (contentieux) | C28: =IF(E28,"Oui","Non") -> 0 | E28: =OR(IFERROR(VLOOKUP(Saisie!C8,P_Classes,4,FALSE)="Oui",FALSE),Saisie!C8="CTX") -> 0
A30: Scores par domaine
A31: Code | B31: Domaine | C31: Score /100 | D31: Poids | E31: Contribution | F31: Poids phase | G31: Contribution phase
A32: =IF(P_General!A16="","",P_General!A16) -> 0 | B32: =IF($A32="","",P_General!B16) -> 0 | C32: =IF($A32="",0,IF(SUMIF($B$44:$B$103,$A32,$G$44:$G$103)>0,ROUND(SUMIF($B$44:$B$103,$A32,$H$44:$H$103)/SUMIF($B$44:$B$103,$A32,$G$44:$G$103)/P_Scale*100,2),0)) -> 0 | D32: =IF($A32="",0,P_General!C16) -> 0 | E32: =IF($A32="",0,ROUND(C32*D32,2)) -> 0 | F32: =IF($A32="",0,IFERROR(INDEX(P_PhaseTbl,MATCH(Saisie!$C$9,P_PhaseCodes,0),MATCH($A32,P_PhaseHdr,0)+1),0)) -> 0 | G32: =ROUND(C32*F32,2) -> 0
A33: =IF(P_General!A17="","",P_General!A17) -> 0 | B33: =IF($A33="","",P_General!B17) -> 0 | C33: =IF($A33="",0,IF(SUMIF($B$44:$B$103,$A33,$G$44:$G$103)>0,ROUND(SUMIF($B$44:$B$103,$A33,$H$44:$H$103)/SUMIF($B$44:$B$103,$A33,$G$44:$G$103)/P_Scale*100,2),0)) -> 0 | D33: =IF($A33="",0,P_General!C17) -> 0 | E33: =IF($A33="",0,ROUND(C33*D33,2)) -> 0 | F33: =IF($A33="",0,IFERROR(INDEX(P_PhaseTbl,MATCH(Saisie!$C$9,P_PhaseCodes,0),MATCH($A33,P_PhaseHdr,0)+1),0)) -> 0 | G33: =ROUND(C33*F33,2) -> 0
A34: =IF(P_General!A18="","",P_General!A18) -> 0 | B34: =IF($A34="","",P_General!B18) -> 0 | C34: =IF($A34="",0,IF(SUMIF($B$44:$B$103,$A34,$G$44:$G$103)>0,ROUND(SUMIF($B$44:$B$103,$A34,$H$44:$H$103)/SUMIF($B$44:$B$103,$A34,$G$44:$G$103)/P_Scale*100,2),0)) -> 0 | D34: =IF($A34="",0,P_General!C18) -> 0 | E34: =IF($A34="",0,ROUND(C34*D34,2)) -> 0 | F34: =IF($A34="",0,IFERROR(INDEX(P_PhaseTbl,MATCH(Saisie!$C$9,P_PhaseCodes,0),MATCH($A34,P_PhaseHdr,0)+1),0)) -> 0 | G34: =ROUND(C34*F34,2) -> 0
A35: =IF(P_General!A19="","",P_General!A19) -> 0 | B35: =IF($A35="","",P_General!B19) -> 0 | C35: =IF($A35="",0,IF(SUMIF($B$44:$B$103,$A35,$G$44:$G$103)>0,ROUND(SUMIF($B$44:$B$103,$A35,$H$44:$H$103)/SUMIF($B$44:$B$103,$A35,$G$44:$G$103)/P_Scale*100,2),0)) -> 0 | D35: =IF($A35="",0,P_General!C19) -> 0 | E35: =IF($A35="",0,ROUND(C35*D35,2)) -> 0 | F35: =IF($A35="",0,IFERROR(INDEX(P_PhaseTbl,MATCH(Saisie!$C$9,P_PhaseCodes,0),MATCH($A35,P_PhaseHdr,0)+1),0)) -> 0 | G35: =ROUND(C35*F35,2) -> 0
A36: =IF(P_General!A20="","",P_General!A20) -> 0 | B36: =IF($A36="","",P_General!B20) -> 0 | C36: =IF($A36="",0,IF(SUMIF($B$44:$B$103,$A36,$G$44:$G$103)>0,ROUND(SUMIF($B$44:$B$103,$A36,$H$44:$H$103)/SUMIF($B$44:$B$103,$A36,$G$44:$G$103)/P_Scale*100,2),0)) -> 0 | D36: =IF($A36="",0,P_General!C20) -> 0 | E36: =IF($A36="",0,ROUND(C36*D36,2)) -> 0 | F36: =IF($A36="",0,IFERROR(INDEX(P_PhaseTbl,MATCH(Saisie!$C$9,P_PhaseCodes,0),MATCH($A36,P_PhaseHdr,0)+1),0)) -> 0 | G36: =ROUND(C36*F36,2) -> 0
A37: =IF(P_General!A21="","",P_General!A21) -> 0 | B37: =IF($A37="","",P_General!B21) -> 0 | C37: =IF($A37="",0,IF(SUMIF($B$44:$B$103,$A37,$G$44:$G$103)>0,ROUND(SUMIF($B$44:$B$103,$A37,$H$44:$H$103)/SUMIF($B$44:$B$103,$A37,$G$44:$G$103)/P_Scale*100,2),0)) -> 0 | D37: =IF($A37="",0,P_General!C21) -> 0 | E37: =IF($A37="",0,ROUND(C37*D37,2)) -> 0 | F37: =IF($A37="",0,IFERROR(INDEX(P_PhaseTbl,MATCH(Saisie!$C$9,P_PhaseCodes,0),MATCH($A37,P_PhaseHdr,0)+1),0)) -> 0 | G37: =ROUND(C37*F37,2) -> 0
A38: =IF(P_General!A22="","",P_General!A22) -> 0 | B38: =IF($A38="","",P_General!B22) -> 0 | C38: =IF($A38="",0,IF(SUMIF($B$44:$B$103,$A38,$G$44:$G$103)>0,ROUND(SUMIF($B$44:$B$103,$A38,$H$44:$H$103)/SUMIF($B$44:$B$103,$A38,$G$44:$G$103)/P_Scale*100,2),0)) -> 0 | D38: =IF($A38="",0,P_General!C22) -> 0 | E38: =IF($A38="",0,ROUND(C38*D38,2)) -> 0 | F38: =IF($A38="",0,IFERROR(INDEX(P_PhaseTbl,MATCH(Saisie!$C$9,P_PhaseCodes,0),MATCH($A38,P_PhaseHdr,0)+1),0)) -> 0 | G38: =ROUND(C38*F38,2) -> 0
A39: =IF(P_General!A23="","",P_General!A23) -> 0 | B39: =IF($A39="","",P_General!B23) -> 0 | C39: =IF($A39="",0,IF(SUMIF($B$44:$B$103,$A39,$G$44:$G$103)>0,ROUND(SUMIF($B$44:$B$103,$A39,$H$44:$H$103)/SUMIF($B$44:$B$103,$A39,$G$44:$G$103)/P_Scale*100,2),0)) -> 0 | D39: =IF($A39="",0,P_General!C23) -> 0 | E39: =IF($A39="",0,ROUND(C39*D39,2)) -> 0 | F39: =IF($A39="",0,IFERROR(INDEX(P_PhaseTbl,MATCH(Saisie!$C$9,P_PhaseCodes,0),MATCH($A39,P_PhaseHdr,0)+1),0)) -> 0 | G39: =ROUND(C39*F39,2) -> 0
A41: Détail par critère (explicabilité)
A42: Code | B42: Domaine | C42: Critère | D42: Clé | E42: Valeur | F42: Note /10 | G42: Poids | H42: Pondéré | I42: Gate franchi | J42: Donnée critique manquante | K42: Note plancher | L42: Nb correspondances | M42: Note brute | N42: Famille | O42: Type | P42: Poids domaine | Q42: Poids effectif | R42: Cumul manquantes | S42: Cumul gates
A43: (clé additionnelle) | D43: =P_ExtraKey -> 0 | E43: =IF(D43="","",IFERROR(INDEX(In_Retenue,MATCH(D43,In_Cles,0)),"")) -> 0 | J43: =AND(D43<>"",E43="") -> 0 | R43: =IF(J43,D43,"") -> 0 | S43: ="" -> 0
A44: =IF(P_Criteres!A5="","",P_Criteres!A5) -> 0 | B44: =IF($A44="","",P_Criteres!B5) -> 0 | C44: =IF($A44="","",P_Criteres!C5) -> 0 | D44: =IF($A44="","",P_Criteres!F5) -> 0 | E44: =IF($A44="","",IFERROR(INDEX(In_Retenue,MATCH($D44,In_Cles,0)),"")) -> 0 | F44: =IF($A44="",0,ROUND(MIN(P_Scale,MAX(0,IF($L44=0,$K44,$M44))),2)) -> 0 | G44: =IF($A44="",0,P_Criteres!E5) -> 0 | H44: =ROUND(F44*G44,2) -> 0 | I44: =IF($A44="",FALSE,AND(P_Criteres!G5="Oui",ISNUMBER(P_Criteres!H5),F44<=N(P_Criteres!H5))) -> 0 | J44: =IF($A44="",FALSE,AND(OR(P_Criteres!G5="Oui",P_Criteres!K5="Oui"),$E44="")) -> 0 | K44: {=IF($A44="",0,MIN(IF(P_Baremes!$A$5:$A$400=$A44,P_Baremes!$H$5:$H$400)))} -> 0 | L44: =IF($A44="",0,IF($O44="NUM",IF(ISNUMBER($E44),SUMPRODUCT((P_Baremes!$A$5:$A$400=$A44)*(P_Baremes!$B$5:$B$400="PLAGE")*(((P_Baremes!$D$5:$D$400="")+($E44>=P_Baremes!$D$5:$D$400))>0)*(((P_Baremes!$E$5:$E$400="")+($E44<P_Baremes!$E$5:$E$400))>0)),0),SUMPRODUCT((P_Baremes!$A$5:$A$400=$A44)*(P_Baremes!$B$5:$B$400="MODALITE")*(P_Baremes!$C$5:$C$400=$E44)))) -> 0 | M44: =IF($A44="",0,IF($L44=0,0,IF($O44="NUM",SUMPRODUCT((P_Baremes!$A$5:$A$400=$A44)*(P_Baremes!$B$5:$B$400="PLAGE")*(((P_Baremes!$D$5:$D$400="")+($E44>=P_Baremes!$D$5:$D$400))>0)*(((P_Baremes!$E$5:$E$400="")+($E44<P_Baremes!$E$5:$E$400))>0)*P_Baremes!$H$5:$H$400),SUMPRODUCT((P_Baremes!$A$5:$A$400=$A44)*(P_Baremes!$B$5:$B$400="MODALITE")*(P_Baremes!$C$5:$C$400=$E44)*P_Baremes!$H$5:$H$400)))) -> 0 | N44: =IF($A44="","",P_Criteres!J5) -> 0 | O44: =IF($A44="","",P_Criteres!D5) -> 0 | P44: =IF($A44="",0,IFERROR(INDEX(P_DomPoids,MATCH($B44,P_DomCodes,0)),0)) -> 0 | Q44: =P44*G44 -> 0 | R44: =IF(J44,IF(ISNUMBER(SEARCH(","&D44&",",","&R43&",")),R43,R43&IF(R43="","",",")&D44),R43) -> 0 | S44: =IF(I44,S43&IF(S43="","",", ")&A44,S43) -> 0
...

Sheet Calculateurs
A1: Calculateurs — alimentent automatiquement les données dérivées (Saisie, colonne « Valeur calculée »)
A2: Une valeur saisie directement dans l'onglet Saisie prime toujours sur ces calculs.
A4: A. Chaîne d'autorisations
A5: Nature du programme | B5: CONSTRUCTION
A7: Code | B7: Pièce | C7: Exigible | D7: Obtenue | E7: Bloque travaux | F7: Bloque livraison | G7: Manquante
A8: =IF(P_Referentiels!A6="","",P_Referentiels!A6) -> 0 | B8: =IF(A8="","",P_Referentiels!B6) -> 0 | C8: =IF(A8="",FALSE,IF($B$5="LOTISSEMENT",P_Referentiels!D6,IF($B$5="CONSTRUCTION",P_Referentiels!E6,P_Referentiels!F6))="Oui") -> 0 | E8: =IF(A8="",FALSE,P_Referentiels!G6="Oui") -> 0 | F8: =IF(A8="",FALSE,P_Referentiels!H6="Oui") -> 0 | G8: =AND(C8,D8<>"Oui") -> 0
A9: =IF(P_Referentiels!A7="","",P_Referentiels!A7) -> 0 | B9: =IF(A9="","",P_Referentiels!B7) -> 0 | C9: =IF(A9="",FALSE,IF($B$5="LOTISSEMENT",P_Referentiels!D7,IF($B$5="CONSTRUCTION",P_Referentiels!E7,P_Referentiels!F7))="Oui") -> 0 | E9: =IF(A9="",FALSE,P_Referentiels!G7="Oui") -> 0 | F9: =IF(A9="",FALSE,P_Referentiels!H7="Oui") -> 0 | G9: =AND(C9,D9<>"Oui") -> 0
A10: =IF(P_Referentiels!A8="","",P_Referentiels!A8) -> 0 | B10: =IF(A10="","",P_Referentiels!B8) -> 0 | C10: =IF(A10="",FALSE,IF($B$5="LOTISSEMENT",P_Referentiels!D8,IF($B$5="CONSTRUCTION",P_Referentiels!E8,P_Referentiels!F8))="Oui") -> 0 | E10: =IF(A10="",FALSE,P_Referentiels!G8="Oui") -> 0 | F10: =IF(A10="",FALSE,P_Referentiels!H8="Oui") -> 0 | G10: =AND(C10,D10<>"Oui") -> 0
A11: =IF(P_Referentiels!A9="","",P_Referentiels!A9) -> 0 | B11: =IF(A11="","",P_Referentiels!B9) -> 0 | C11: =IF(A11="",FALSE,IF($B$5="LOTISSEMENT",P_Referentiels!D9,IF($B$5="CONSTRUCTION",P_Referentiels!E9,P_Referentiels!F9))="Oui") -> 0 | E11: =IF(A11="",FALSE,P_Referentiels!G9="Oui") -> 0 | F11: =IF(A11="",FALSE,P_Referentiels!H9="Oui") -> 0 | G11: =AND(C11,D11<>"Oui") -> 0
A12: =IF(P_Referentiels!A10="","",P_Referentiels!A10) -> 0 | B12: =IF(A12="","",P_Referentiels!B10) -> 0 | C12: =IF(A12="",FALSE,IF($B$5="LOTISSEMENT",P_Referentiels!D10,IF($B$5="CONSTRUCTION",P_Referentiels!E10,P_Referentiels!F10))="Oui") -> 0 | E12: =IF(A12="",FALSE,P_Referentiels!G10="Oui") -> 0 | F12: =IF(A12="",FALSE,P_Referentiels!H10="Oui") -> 0 | G12: =AND(C12,D12<>"Oui") -> 0
A13: =IF(P_Referentiels!A11="","",P_Referentiels!A11) -> 0 | B13: =IF(A13="","",P_Referentiels!B11) -> 0 | C13: =IF(A13="",FALSE,IF($B$5="LOTISSEMENT",P_Referentiels!D11,IF($B$5="CONSTRUCTION",P_Referentiels!E11,P_Referentiels!F11))="Oui") -> 0 | E13: =IF(A13="",FALSE,P_Referentiels!G11="Oui") -> 0 | F13: =IF(A13="",FALSE,P_Referentiels!H11="Oui") -> 0 | G13: =AND(C13,D13<>"Oui") -> 0
A14: =IF(P_Referentiels!A12="","",P_Referentiels!A12) -> 0 | B14: =IF(A14="","",P_Referentiels!B12) -> 0 | C14: =IF(A14="",FALSE,IF($B$5="LOTISSEMENT",P_Referentiels!D12,IF($B$5="CONSTRUCTION",P_Referentiels!E12,P_Referentiels!F12))="Oui") -> 0 | E14: =IF(A14="",FALSE,P_Referentiels!G12="Oui") -> 0 | F14: =IF(A14="",FALSE,P_Referentiels!H12="Oui") -> 0 | G14: =AND(C14,D14<>"Oui") -> 0
A15: =IF(P_Referentiels!A13="","",P_Referentiels!A13) -> 0 | B15: =IF(A15="","",P_Referentiels!B13) -> 0 | C15: =IF(A15="",FALSE,IF($B$5="LOTISSEMENT",P_Referentiels!D13,IF($B$5="CONSTRUCTION",P_Referentiels!E13,P_Referentiels!F13))="Oui") -> 0 | E15: =IF(A15="",FALSE,P_Referentiels!G13="Oui") -> 0 | F15: =IF(A15="",FALSE,P_Referentiels!H13="Oui") -> 0 | G15: =AND(C15,D15<>"Oui") -> 0
A16: =IF(P_Referentiels!A14="","",P_Referentiels!A14) -> 0 | B16: =IF(A16="","",P_Referentiels!B14) -> 0 | C16: =IF(A16="",FALSE,IF($B$5="LOTISSEMENT",P_Referentiels!D14,IF($B$5="CONSTRUCTION",P_Referentiels!E14,P_Referentiels!F14))="Oui") -> 0 | E16: =IF(A16="",FALSE,P_Referentiels!G14="Oui") -> 0 | F16: =IF(A16="",FALSE,P_Referentiels!H14="Oui") -> 0 | G16: =AND(C16,D16<>"Oui") -> 0
A17: =IF(P_Referentiels!A15="","",P_Referentiels!A15) -> 0 | B17: =IF(A17="","",P_Referentiels!B15) -> 0 | C17: =IF(A17="",FALSE,IF($B$5="LOTISSEMENT",P_Referentiels!D15,IF($B$5="CONSTRUCTION",P_Referentiels!E15,P_Referentiels!F15))="Oui") -> 0 | E17: =IF(A17="",FALSE,P_Referentiels!G15="Oui") -> 0 | F17: =IF(A17="",FALSE,P_Referentiels!H15="Oui") -> 0 | G17: =AND(C17,D17<>"Oui") -> 0
A18: =IF(P_Referentiels!A16="","",P_Referentiels!A16) -> 0 | B18: =IF(A18="","",P_Referentiels!B16) -> 0 | C18: =IF(A18="",FALSE,IF($B$5="LOTISSEMENT",P_Referentiels!D16,IF($B$5="CONSTRUCTION",P_Referentiels!E16,P_Referentiels!F16))="Oui") -> 0 | E18: =IF(A18="",FALSE,P_Referentiels!G16="Oui") -> 0 | F18: =IF(A18="",FALSE,P_Referentiels!H16="Oui") -> 0 | G18: =AND(C18,D18<>"Oui") -> 0
A19: =IF(P_Referentiels!A17="","",P_Referentiels!A17) -> 0 | B19: =IF(A19="","",P_Referentiels!B17) -> 0 | C19: =IF(A19="",FALSE,IF($B$5="LOTISSEMENT",P_Referentiels!D17,IF($B$5="CONSTRUCTION",P_Referentiels!E17,P_Referentiels!F17))="Oui") -> 0 | E19: =IF(A19="",FALSE,P_Referentiels!G17="Oui") -> 0 | F19: =IF(A19="",FALSE,P_Referentiels!H17="Oui") -> 0 | G19: =AND(C19,D19<>"Oui") -> 0
... A31: =IF(P_Referentiels!A29="","",P_Referentiels!A29) -> 0 | B31: =IF(A31="","",P_Referentiels!B29) -> 0 | C31: =IF(A31="",FALSE,IF($B$5="LOTISSEMENT",P_Referentiels!D29,IF($B$5="CONSTRUCTION",P_Referentiels!E29,P_Referentiels!F29))="Oui") -> 0 | E31: =IF(A31="",FALSE,P_Referentiels!G29="Oui") -> 0 | F31: =IF(A31="",FALSE,P_Referentiels!H29="Oui") -> 0 | G31: =AND(C31,D31<>"Oui") -> 0
A33: Complétude de la chaîne (%) | C33: =IF(SUMPRODUCT((C8:C31=TRUE)*1)=0,100,ROUND(SUMPRODUCT((C8:C31=TRUE)*(D8:D31="Oui"))/SUMPRODUCT((C8:C31=TRUE)*1)*100,2)) -> 0
A34: Verrou de travaux (pièce indispensable manquante) | C34: =SUMPRODUCT((G8:G31=TRUE)*(E8:E31=TRUE))>0 -> 0
A35: Saisie de la chaîne effectuée ? | C35: =COUNTIF(D8:D31,"Oui")+COUNTIF(D8:D31,"Non")>0 -> 0
A38: B. Ventes sécurisées (financement de l'acquéreur)
A39: Valeur commercialisable totale (MAD) | D39: vide = somme des prix des lots ci-dessous
A41: Lot | B41: Statut de financement acquéreur | C41: Prix (MAD) | D41: Engagé juridiquement | E41: Facteur | F41: Renseigné | G41: À risque
E42: =IF(B42="",0,IFERROR(VLOOKUP(B42,R_FinTbl,3,FALSE),0.2)) -> 0 | F42: =B42<>"" -> 0 | G42: =AND(B42<>"",D42<>"Non",E42<=0.4) -> 0
E43: =IF(B43="",0,IFERROR(VLOOKUP(B43,R_FinTbl,3,FALSE),0.2)) -> 0 | F43: =B43<>"" -> 0 | G43: =AND(B43<>"",D43<>"Non",E43<=0.4) -> 0
E44: =IF(B44="",0,IFERROR(VLOOKUP(B44,R_FinTbl,3,FALSE),0.2)) -> 0 | F44: =B44<>"" -> 0 | G44: =AND(B44<>"",D44<>"Non",E44<=0.4) -> 0
E45: =IF(B45="",0,IFERROR(VLOOKUP(B45,R_FinTbl,3,FALSE),0.2)) -> 0 | F45: =B45<>"" -> 0 | G45: =AND(B45<>"",D45<>"Non",E45<=0.4) -> 0
E46: =IF(B46="",0,IFERROR(VLOOKUP(B46,R_FinTbl,3,FALSE),0.2)) -> 0 | F46: =B46<>"" -> 0 | G46: =AND(B46<>"",D46<>"Non",E46<=0.4) -> 0
E47: =IF(B47="",0,IFERROR(VLOOKUP(B47,R_FinTbl,3,FALSE),0.2)) -> 0 | F47: =B47<>"" -> 0 | G47: =AND(B47<>"",D47<>"Non",E47<=0.4) -> 0
E48: =IF(B48="",0,IFERROR(VLOOKUP(B48,R_FinTbl,3,FALSE),0.2)) -> 0 | F48: =B48<>"" -> 0 | G48: =AND(B48<>"",D48<>"Non",E48<=0.4) -> 0
E49: =IF(B49="",0,IFERROR(VLOOKUP(B49,R_FinTbl,3,FALSE),0.2)) -> 0 | F49: =B49<>"" -> 0 | G49: =AND(B49<>"",D49<>"Non",E49<=0.4) -> 0
E50: =IF(B50="",0,IFERROR(VLOOKUP(B50,R_FinTbl,3,FALSE),0.2)) -> 0 | F50: =B50<>"" -> 0 | G50: =AND(B50<>"",D50<>"Non",E50<=0.4) -> 0
E51: =IF(B51="",0,IFERROR(VLOOKUP(B51,R_FinTbl,3,FALSE),0.2)) -> 0 | F51: =B51<>"" -> 0 | G51: =AND(B51<>"",D51<>"Non",E51<=0.4) -> 0
E52: =IF(B52="",0,IFERROR(VLOOKUP(B52,R_FinTbl,3,FALSE),0.2)) -> 0 | F52: =B52<>"" -> 0 | G52: =AND(B52<>"",D52<>"Non",E52<=0.4) -> 0
E53: =IF(B53="",0,IFERROR(VLOOKUP(B53,R_FinTbl,3,FALSE),0.2)) -> 0 | F53: =B53<>"" -> 0 | G53: =AND(B53<>"",D53<>"Non",E53<=0.4) -> 0
... E81: =IF(B81="",0,IFERROR(VLOOKUP(B81,R_FinTbl,3,FALSE),0.2)) -> 0 | F81: =B81<>"" -> 0 | G81: =AND(B81<>"",D81<>"Non",E81<=0.4) -> 0
A83: Chiffre d'affaires engagé (MAD) | C83: =SUMPRODUCT((F42:F81=TRUE)*(D42:D81<>"Non")*C42:C81) -> 0
A84: Chiffre d'affaires sécurisé (MAD) | C84: =SUMPRODUCT((F42:F81=TRUE)*(D42:D81<>"Non")*C42:C81*E42:E81) -> 0
A85: Taux de ventes sécurisées (%) | C85: =IF(SUMPRODUCT((F42:F81=TRUE)*1)=0,"",IF(IF(C39="",SUM(C42:C81),C39)>0,ROUND(C84/IF(C39="",SUM(C42:C81),C39)*100,2),"")) -> 0
...

Sheet Portefeuille
A1: Scoring de portefeuille
A2: Une ligne par dossier. Les valeurs Oui/Non pour les booléens. Macro : ScorerPortefeuille (Alt+F8) — remplit les colonnes de résultat à droite.
A3: Identité | F3: Données d'entrée (mêmes clés que l'onglet Saisie)
A4: Référence | B4: Nom du projet | C4: Segment | D4: Zone | E4: Classe BAM | F4: promoter_completed_projects | G4: promoter_gearing | H4: governance_quality | I4: mono_project_concentration | J4: promoter_type | K4: equity_injected_ratio | L4: land_permits_status | M4: market_positioning | N4: technical_complexity | O4: progress_vs_plan | P4: sav_litigation | Q4: macro_sensitivity | R4: land_cost_ratio | S4: authorization_completeness_pct | T4: pre_sale_rate | U4: sales_vs_plan | V4: dso_days | W4: cash_coverage | X4: funding_gap_pct | Y4: stock_rotation_months | Z4: stressed_margin_pct | AA4: secured_sales_rate | AB4: gross_margin_pct | AC4: ltc | AD4: ltv_stressed | AE4: guarantee_coverage | AF4: first_rank | AG4: interest_coverage | AH4: release_quotity_gap_pts | AI4: dpd_days | AJ4: construction_delay_months | AK4: project_stopped_months | AL4: restructured | AM4: legal_exposure | AN4: equity_negative | AO4: funding_gap_persistent | AP4: works_authorization_blocked | AQ4: buyers_financing_at_risk | AR4: release_underpriced | AS4: division_limit_breach | AT4: Score final | AU4: Décision | AV4: Classe interne | AW4: Malus D5 | AX4: Dossier complet | AY4: D1 | AZ4: D2 | BA4: D3 | BB4: D4 | BC4: Score éco. | BD4: Note sûretés | BE4: PD indicative | BF4: Alertes
A5: EXEMPLE-1 | B5: Dossier solide, classe saine | E5: SAIN | F5: 8 | G5: 85 | H5: claire | I5: 35 | J5: structure | K5: 100 | L5: definitives | M5: aligne | N5: standard | O5: 100 | P5: faible | Q5: faible | R5: 22 | S5: 100 | T5: 62 | U5: 100 | V5: 90 | W5: 1.35 | X5: 0 | Y5: 16 | Z5: 18 | AA5: 55 | AB5: 27 | AC5: 61 | AD5: 65 | AE5: 125 | AF5: oui | AG5: 3.2 | AH5: 5 | AI5: 0 | AJ5: 0 | AK5: 0 | AL5: no | AM5: clear | AN5: Non | AO5: Non | AP5: Non | AQ5: Non | AR5: Non | AS5: Non
A6: EXEMPLE-2 | B6: Dossier intermédiaire (score moyen) | C6: intermediaire | D6: casa_peripherie | E6: SAIN | F6: 2 | G6: 120 | H6: partielle | I6: 50 | J6: regional | K6: 90 | L6: partielles | M6: moyen | N6: moyenne | O6: 90 | P6: moyen | Q6: moyenne | R6: 30 | S6: 70 | T6: 35 | U6: 90 | V6: 180 | W6: 1.1 | X6: 5 | Y6: 24 | Z6: 12 | AA6: 30 | AB6: 20 | AC6: 70 | AD6: 78 | AE6: 100 | AF6: oui | AG6: 2 | AH6: -5 | AI6: 0 | AJ6: 0 | AK6: 0 | AL6: no | AM6: clear | AN6: Non | AO6: Non | AP6: Non | AQ6: Non | AR6: Non | AS6: Non
A7: EXEMPLE-3 | B7: Non 1er rang + restructuration : malus cumulés | E7: SAIN | F7: 8 | G7: 85 | H7: claire | I7: 35 | J7: structure | K7: 100 | L7: definitives | M7: aligne | N7: standard | O7: 100 | P7: faible | Q7: faible | R7: 22 | S7: 100 | T7: 62 | U7: 100 | V7: 90 | W7: 1.35 | X7: 0 | Y7: 16 | Z7: 18 | AA7: 55 | AB7: 27 | AC7: 61 | AD7: 65 | AE7: 125 | AF7: non | AG7: 3.2 | AH7: 5 | AI7: 0 | AJ7: 0 | AK7: 0 | AL7: yes | AM7: clear | AN7: Non | AO7: Non | AP7: Non | AQ7: Non | AR7: Non | AS7: Non

Sheet Stress
A1: Stress test sur le dossier courant (onglet Saisie)
A2: Chocs appliqués aux données primitives par identités comptables (marge, LTV, LTC) — mêmes règles que l'application. Macro : LancerStress.
A3: Score de base | D3: Décision de base
A4: Scénario | B4: Libellé | C4: Prix −% | D4: Coût +% | E4: Retard (mois) | F4: Ventes −% | G4: Taux +bps | H4: Préventes −pts | I4: Retard paiement +j | J4: Score final | K4: Décision | L4: Δ vs base
A5: price10 | B5: Prix −10 % | C5: 10 | D5: 0 | E5: 0 | F5: 0 | G5: 0 | H5: 0 | I5: 0
A6: price15 | B6: Prix −15 % | C6: 15 | D6: 0 | E6: 0 | F6: 0 | G6: 0 | H6: 0 | I6: 0
A7: cost10 | B7: Coût +10 % | C7: 0 | D7: 10 | E7: 0 | F7: 0 | G7: 0 | H7: 0 | I7: 0
A8: delay6 | B8: Retard +6 mois | C8: 0 | D8: 0 | E8: 6 | F8: 0 | G8: 0 | H8: 0 | I8: 0
A9: sales20 | B9: Ventes −20 % | C9: 0 | D9: 0 | E9: 0 | F9: 20 | G9: 0 | H9: 0 | I9: 0
A10: rate200 | B10: Taux +200 bps | C10: 0 | D10: 0 | E10: 0 | F10: 0 | G10: 200 | H10: 0 | I10: 0
A11: severe | B11: Sévère combiné | C11: 15 | D11: 10 | E11: 6 | F11: 20 | G11: 200 | H11: 0 | I11: 0

Sheet Tests
A1: Autotests — cas de référence issus du moteur de production
A2: Les résultats attendus proviennent de l'exécution du moteur de l'application sur le modèle v4.0.0. Macro : ExecuterAutotests (tolérance 0,02 point).
A3: Identité | F3: Données d'entrée (mêmes clés que l'onglet Saisie)
A4: Cas | B4: Description | C4: Segment | D4: Zone | E4: Classe BAM | F4: promoter_completed_projects | G4: promoter_gearing | H4: governance_quality | I4: mono_project_concentration | J4: promoter_type | K4: equity_injected_ratio | L4: land_permits_status | M4: market_positioning | N4: technical_complexity | O4: progress_vs_plan | P4: sav_litigation | Q4: macro_sensitivity | R4: land_cost_ratio | S4: authorization_completeness_pct | T4: pre_sale_rate | U4: sales_vs_plan | V4: dso_days | W4: cash_coverage | X4: funding_gap_pct | Y4: stock_rotation_months | Z4: stressed_margin_pct | AA4: secured_sales_rate | AB4: gross_margin_pct | AC4: ltc | AD4: ltv_stressed | AE4: guarantee_coverage | AF4: first_rank | AG4: interest_coverage | AH4: release_quotity_gap_pts | AI4: dpd_days | AJ4: construction_delay_months | AK4: project_stopped_months | AL4: restructured | AM4: legal_exposure | AN4: equity_negative | AO4: funding_gap_persistent | AP4: works_authorization_blocked | AQ4: buyers_financing_at_risk | AR4: release_underpriced | AS4: division_limit_breach | AT4: Attendu : score final | AU4: Attendu : décision | AV4: Attendu : classe interne | AW4: Attendu : malus | AX4: Attendu : incomplet | AY4: Attendu : score éco. | AZ4: Attendu : D1 | BA4: Attendu : D2 | BB4: Attendu : D3 | BC4: Attendu : D4 | BD4: Attendu : note sûretés | BE4: Obtenu : score final | BF4: Obtenu : décision | BG4: Statut
A5: T01 | B5: Dossier solide, classe saine | E5: SAIN | F5: 8 | G5: 85 | H5: claire | I5: 35 | J5: structure | K5: 100 | L5: definitives | M5: aligne | N5: standard | O5: 100 | P5: faible | Q5: faible | R5: 22 | S5: 100 | T5: 62 | U5: 100 | V5: 90 | W5: 1.35 | X5: 0 | Y5: 16 | Z5: 18 | AA5: 55 | AB5: 27 | AC5: 61 | AD5: 65 | AE5: 125 | AF5: oui | AG5: 3.2 | AH5: 5 | AI5: 0 | AJ5: 0 | AK5: 0 | AL5: no | AM5: clear | AN5: Non | AO5: Non | AP5: Non | AQ5: Non | AR5: Non | AS5: Non | AT5: 98.56 | AU5: GO | AV5: Sain | AW5: 0 | AX5: Non | AY5: 98.56 | AZ5: 100 | BA5: 100 | BB5: 100 | BC5: 94 | BD5: 100
A6: T02 | B6: Solide, segment touristique + zone Marrakech (ajustements) | C6: touristique | D6: marrakech | E6: SAIN | F6: 8 | G6: 85 | H6: claire | I6: 35 | J6: structure | K6: 100 | L6: definitives | M6: aligne | N6: standard | O6: 100 | P6: faible | Q6: faible | R6: 22 | S6: 100 | T6: 62 | U6: 100 | V6: 90 | W6: 1.35 | X6: 0 | Y6: 16 | Z6: 18 | AA6: 55 | AB6: 27 | AC6: 61 | AD6: 65 | AE6: 125 | AF6: oui | AG6: 3.2 | AH6: 5 | AI6: 0 | AJ6: 0 | AK6: 0 | AL6: no | AM6: clear | AN6: Non | AO6: Non | AP6: Non | AQ6: Non | AR6: Non | AS6: Non | AT6: 84.76 | AU6: GO | AV6: Sain | AW6: 0 | AX6: Non | AY6: 98.56 | AZ6: 100 | BA6: 100 | BB6: 100 | BC6: 94 | BD6: 100
A7: T03 | B7: Dossier intermédiaire (score moyen) | C7: intermediaire | D7: casa_peripherie | E7: SAIN | F7: 2 | G7: 120 | H7: partielle | I7: 50 | J7: regional | K7: 90 | L7: partielles | M7: moyen | N7: moyenne | O7: 90 | P7: moyen | Q7: moyenne | R7: 30 | S7: 70 | T7: 35 | U7: 90 | V7: 180 | W7: 1.1 | X7: 5 | Y7: 24 | Z7: 12 | AA7: 30 | AB7: 20 | AC7: 70 | AD7: 78 | AE7: 100 | AF7: oui | AG7: 2 | AH7: -5 | AI7: 0 | AJ7: 0 | AK7: 0 | AL7: no | AM7: clear | AN7: Non | AO7: Non | AP7: Non | AQ7: Non | AR7: Non | AS7: Non | AT7: 54.86 | AU7: WATCH_LIST | AV7: Sensible probable | AW7: 0 | AX7: Non | AY7: 60.96 | AZ7: 60 | BA7: 60 | BB7: 60 | BC7: 64 | BD7: 68
A8: T04 | B8: Dossier intermédiaire dégradé (cash 0,9 + impasse persistante) | E8: SAIN | F8: 2 | G8: 120 | H8: partielle | I8: 50 | J8: regional | K8: 90 | L8: partielles | M8: moyen | N8: moyenne | O8: 90 | P8: moyen | Q8: moyenne | R8: 30 | S8: 70 | T8: 35 | U8: 90 | V8: 180 | W8: 0.9 | X8: 5 | Y8: 24 | Z8: 12 | AA8: 30 | AB8: 20 | AC8: 70 | AD8: 78 | AE8: 100 | AF8: oui | AG8: 2 | AH8: -5 | AI8: 0 | AJ8: 0 | AK8: 0 | AL8: no | AM8: clear | AN8: Non | AO8: Oui | AP8: Non | AQ8: Non | AR8: Non | AS8: Non | AT8: 12.86 | AU8: NO_GO | AV8: Sensible | AW8: 45 | AX8: Non | AY8: 57.86 | AZ8: 60 | BA8: 60 | BB8: 50 | BC8: 64 | BD8: 68
A9: T05 | B9: Impayé 120 j : alerte bloquante, souffrance | E9: SAIN | F9: 8 | G9: 85 | H9: claire | I9: 35 | J9: structure | K9: 100 | L9: definitives | M9: aligne | N9: standard | O9: 100 | P9: faible | Q9: faible | R9: 22 | S9: 100 | T9: 62 | U9: 100 | V9: 90 | W9: 1.35 | X9: 0 | Y9: 16 | Z9: 18 | AA9: 55 | AB9: 27 | AC9: 61 | AD9: 65 | AE9: 125 | AF9: oui | AG9: 3.2 | AH9: 5 | AI9: 120 | AJ9: 0 | AK9: 0 | AL9: no | AM9: clear | AN9: Non | AO9: Non | AP9: Non | AQ9: Non | AR9: Non | AS9: Non | AT9: 98.56 | AU9: NO_GO | AV9: Souffrance | AW9: 0 | AX9: Non | AY9: 98.56 | AZ9: 100 | BA9: 100 | BB9: 100 | BC9: 94 | BD9: 100
A10: T06 | B10: Cash coverage 0,99 : alerte -25 | E10: SAIN | F10: 8 | G10: 85 | H10: claire | I10: 35 | J10: structure | K10: 100 | L10: definitives | M10: aligne | N10: standard | O10: 100 | P10: faible | Q10: faible | R10: 22 | S10: 100 | T10: 62 | U10: 100 | V10: 90 | W10: 0.99 | X10: 0 | Y10: 16 | Z10: 18 | AA10: 55 | AB10: 27 | AC10: 61 | AD10: 65 | AE10: 125 | AF10: oui | AG10: 3.2 | AH10: 5 | AI10: 0 | AJ10: 0 | AK10: 0 | AL10: no | AM10: clear | AN10: Non | AO10: Non | AP10: Non | AQ10: Non | AR10: Non | AS10: Non | AT10: 67.98 | AU10: GO_WITH_CONDITIONS | AV10: Surveillance | AW10: 25 | AX10: Non | AY10: 92.98 | AZ10: 100 | BA10: 100 | BB10: 82 | BC10: 94 | BD10: 100
A11: T07 | B11: Cash coverage absent : dossier incomplet | E11: SAIN | F11: 8 | G11: 85 | H11: claire | I11: 35 | J11: structure | K11: 100 | L11: definitives | M11: aligne | N11: standard | O11: 100 | P11: faible | Q11: faible | R11: 22 | S11: 100 | T11: 62 | U11: 100 | V11: 90 | X11: 0 | Y11: 16 | Z11: 18 | AA11: 55 | AB11: 27 | AC11: 61 | AD11: 65 | AE11: 125 | AF11: oui | AG11: 3.2 | AH11: 5 | AI11: 0 | AJ11: 0 | AK11: 0 | AL11: no | AM11: clear | AN11: Non | AO11: Non | AP11: Non | AQ11: Non | AR11: Non | AS11: Non | AT11: 67.98 | AU11: DOSSIER_INCOMPLET | AV11: Dossier incomplet | AW11: 25 | AX11: Oui | AY11: 92.98 | AZ11: 100 | BA11: 100 | BB11: 82 | BC11: 94 | BD11: 100
A12: T08 | B12: Classe pré-douteuse : défaut avéré | E12: PRE_DOUTEUX | F12: 8 | G12: 85 | H12: claire | I12: 35 | J12: structure | K12: 100 | L12: definitives | M12: aligne | N12: standard | O12: 100 | P12: faible | Q12: faible | R12: 22 | S12: 100 | T12: 62 | U12: 100 | V12: 90 | W12: 1.35 | X12: 0 | Y12: 16 | Z12: 18 | AA12: 55 | AB12: 27 | AC12: 61 | AD12: 65 | AE12: 125 | AF12: oui | AG12: 3.2 | AH12: 5 | AI12: 0 | AJ12: 0 | AK12: 0 | AL12: no | AM12: clear | AN12: Non | AO12: Non | AP12: Non | AQ12: Non | AR12: Non | AS12: Non | AT12: 68.99 | AU12: NO_GO | AV12: Défaut avéré | AW12: 0 | AX12: Non | AY12: 98.56 | AZ12: 100 | BA12: 100 | BB12: 100 | BC12: 94 | BD12: 100
A13: T09 | B13: Classe contentieux CTX : score 0 | E13: CTX | F13: 8 | G13: 85 | H13: claire | I13: 35 | J13: structure | K13: 100 | L13: definitives | M13: aligne | N13: standard | O13: 100 | P13: faible | Q13: faible | R13: 22 | S13: 100 | T13: 62 | U13: 100 | V13: 90 | W13: 1.35 | X13: 0 | Y13: 16 | Z13: 18 | AA13: 55 | AB13: 27 | AC13: 61 | AD13: 65 | AE13: 125 | AF13: oui | AG13: 3.2 | AH13: 5 | AI13: 0 | AJ13: 0 | AK13: 0 | AL13: no | AM13: clear | AN13: Non | AO13: Non | AP13: Non | AQ13: Non | AR13: Non | AS13: Non | AT13: 0 | AU13: NO_GO | AV13: Souffrance | AW13: 0 | AX13: Non | AY13: 98.56 | AZ13: 100 | BA13: 100 | BB13: 100 | BC13: 94 | BD13: 100
A14: T10 | B14: Classe sensible : coefficient 0,9 | E14: SENSIBLE | F14: 8 | G14: 85 | H14: claire | I14: 35 | J14: structure | K14: 100 | L14: definitives | M14: aligne | N14: standard | O14: 100 | P14: faible | Q14: faible | R14: 22 | S14: 100 | T14: 62 | U14: 100 | V14: 90 | W14: 1.35 | X14: 0 | Y14: 16 | Z14: 18 | AA14: 55 | AB14: 27 | AC14: 61 | AD14: 65 | AE14: 125 | AF14: oui | AG14: 3.2 | AH14: 5 | AI14: 0 | AJ14: 0 | AK14: 0 | AL14: no | AM14: clear | AN14: Non | AO14: Non | AP14: Non | AQ14: Non | AR14: Non | AS14: Non | AT14: 88.7 | AU14: GO | AV14: Sain | AW14: 0 | AX14: Non | AY14: 98.56 | AZ14: 100 | BA14: 100 | BB14: 100 | BC14: 94 | BD14: 100
A15: T11 | B15: Apport 50 % : gate franchi | E15: SAIN | F15: 8 | G15: 85 | H15: claire | I15: 35 | J15: structure | K15: 50 | L15: definitives | M15: aligne | N15: standard | O15: 100 | P15: faible | Q15: faible | R15: 22 | S15: 100 | T15: 62 | U15: 100 | V15: 90 | W15: 1.35 | X15: 0 | Y15: 16 | Z15: 18 | AA15: 55 | AB15: 27 | AC15: 61 | AD15: 65 | AE15: 125 | AF15: oui | AG15: 3.2 | AH15: 5 | AI15: 0 | AJ15: 0 | AK15: 0 | AL15: no | AM15: clear | AN15: Non | AO15: Non | AP15: Non | AQ15: Non | AR15: Non | AS15: Non | AT15: 95.19 | AU15: NO_GO | AV15: Sain | AW15: 0 | AX15: Non | AY15: 95.19 | AZ15: 86.5 | BA15: 100 | BB15: 100 | BC15: 94 | BD15: 100
A16: T12 | B16: Non 1er rang + restructuration : malus cumulés | E16: SAIN | F16: 8 | G16: 85 | H16: claire | I16: 35 | J16: structure | K16: 100 | L16: definitives | M16: aligne | N16: standard | O16: 100 | P16: faible | Q16: faible | R16: 22 | S16: 100 | T16: 62 | U16: 100 | V16: 90 | W16: 1.35 | X16: 0 | Y16: 16 | Z16: 18 | AA16: 55 | AB16: 27 | AC16: 61 | AD16: 65 | AE16: 125 | AF16: non | AG16: 3.2 | AH16: 5 | AI16: 0 | AJ16: 0 | AK16: 0 | AL16: yes | AM16: clear | AN16: Non | AO16: Non | AP16: Non | AQ16: Non | AR16: Non | AS16: Non | AT16: 46.4 | AU16: NO_GO | AV16: Sensible | AW16: 50 | AX16: Non | AY16: 96.4 | AZ16: 100 | BA16: 100 | BB16: 100 | BC16: 85 | BD16: 82
A17: T13 | B17: Segment et zone hors référentiel | C17: segment_inconnu | D17: zone_inconnue | E17: SAIN | F17: 8 | G17: 85 | H17: claire | I17: 35 | J17: structure | K17: 100 | L17: definitives | M17: aligne | N17: standard | O17: 100 | P17: faible | Q17: faible | R17: 22 | S17: 100 | T17: 62 | U17: 100 | V17: 90 | W17: 1.35 | X17: 0 | Y17: 16 | Z17: 18 | AA17: 55 | AB17: 27 | AC17: 61 | AD17: 65 | AE17: 125 | AF17: oui | AG17: 3.2 | AH17: 5 | AI17: 0 | AJ17: 0 | AK17: 0 | AL17: no | AM17: clear | AN17: Non | AO17: Non | AP17: Non | AQ17: Non | AR17: Non | AS17: Non | AT17: 98.56 | AU17: GO | AV17: Sain | AW17: 0 | AX17: Non | AY17: 98.56 | AZ17: 100 | BA17: 100 | BB17: 100 | BC17: 94 | BD17: 100
A18: T14 | B18: Classe non renseignée : dossier incomplet | F18: 8 | G18: 85 | H18: claire | I18: 35 | J18: structure | K18: 100 | L18: definitives | M18: aligne | N18: standard | O18: 100 | P18: faible | Q18: faible | R18: 22 | S18: 100 | T18: 62 | U18: 100 | V18: 90 | W18: 1.35 | X18: 0 | Y18: 16 | Z18: 18 | AA18: 55 | AB18: 27 | AC18: 61 | AD18: 65 | AE18: 125 | AF18: oui | AG18: 3.2 | AH18: 5 | AI18: 0 | AJ18: 0 | AK18: 0 | AL18: no | AM18: clear | AN18: Non | AO18: Non | AP18: Non | AQ18: Non | AR18: Non | AS18: Non | AT18: 98.56 | AU18: DOSSIER_INCOMPLET | AV18: Dossier incomplet | AW18: 0 | AX18: Oui | AY18: 98.56 | AZ18: 100 | BA18: 100 | BB18: 100 | BC18: 94 | BD18: 100
A19: T15 | B19: Autorisation indispensable manquante (verrou de tirage) | E19: SAIN | F19: 8 | G19: 85 | H19: claire | I19: 35 | J19: structure | K19: 100 | L19: definitives | M19: aligne | N19: standard | O19: 100 | P19: faible | Q19: faible | R19: 22 | S19: 40 | T19: 62 | U19: 100 | V19: 90 | W19: 1.35 | X19: 0 | Y19: 16 | Z19: 18 | AA19: 55 | AB19: 27 | AC19: 61 | AD19: 65 | AE19: 125 | AF19: oui | AG19: 3.2 | AH19: 5 | AI19: 0 | AJ19: 0 | AK19: 0 | AL19: no | AM19: clear | AN19: Non | AO19: Non | AP19: Oui | AQ19: Non | AR19: Non | AS19: Non | AT19: 81.76 | AU19: GO | AV19: Sain | AW19: 15 | AX19: Non | AY19: 96.76 | AZ19: 100 | BA19: 91 | BB19: 100 | BC19: 94 | BD19: 100
A20: T16 | B20: Gouvernance non renseignée (qualitatif : note plancher) | E20: SAIN | F20: 8 | G20: 85 | I20: 35 | J20: structure | K20: 100 | L20: definitives | M20: aligne | N20: standard | O20: 100 | P20: faible | Q20: faible | R20: 22 | S20: 100 | T20: 62 | U20: 100 | V20: 90 | W20: 1.35 | X20: 0 | Y20: 16 | Z20: 18 | AA20: 55 | AB20: 27 | AC20: 61 | AD20: 65 | AE20: 125 | AF20: oui | AG20: 3.2 | AH20: 5 | AI20: 0 | AJ20: 0 | AK20: 0 | AL20: no | AM20: clear | AN20: Non | AO20: Non | AP20: Non | AQ20: Non | AR20: Non | AS20: Non | AT20: 95.19 | AU20: GO | AV20: Sain | AW20: 0 | AX20: Non | AY20: 95.19 | AZ20: 86.5 | BA20: 100 | BB20: 100 | BC20: 94 | BD20: 100
A21: T17 | B21: Retard chantier 8 mois + prix de mainlevée sous-tarifé | E21: SAIN | F21: 8 | G21: 85 | H21: claire | I21: 35 | J21: structure | K21: 100 | L21: definitives | M21: aligne | N21: standard | O21: 100 | P21: faible | Q21: faible | R21: 22 | S21: 100 | T21: 62 | U21: 100 | V21: 90 | W21: 1.35 | X21: 0 | Y21: 16 | Z21: 18 | AA21: 55 | AB21: 27 | AC21: 61 | AD21: 65 | AE21: 125 | AF21: oui | AG21: 3.2 | AH21: -15 | AI21: 0 | AJ21: 8 | AK21: 0 | AL21: no | AM21: clear | AN21: Non | AO21: Non | AP21: Non | AQ21: Non | AR21: Oui | AS21: Non | AT21: 67.48 | AU21: GO_WITH_CONDITIONS | AV21: Surveillance | AW21: 30 | AX21: Non | AY21: 97.48 | AZ21: 100 | BA21: 100 | BB21: 100 | BC21: 89.5 | BD21: 91
A22: T18 | B22: Retard de paiement (dpd_days) absent : dossier incomplet | E22: SAIN | F22: 8 | G22: 85 | H22: claire | I22: 35 | J22: structure | K22: 100 | L22: definitives | M22: aligne | N22: standard | O22: 100 | P22: faible | Q22: faible | R22: 22 | S22: 100 | T22: 62 | U22: 100 | V22: 90 | W22: 1.35 | X22: 0 | Y22: 16 | Z22: 18 | AA22: 55 | AB22: 27 | AC22: 61 | AD22: 65 | AE22: 125 | AF22: oui | AG22: 3.2 | AH22: 5 | AJ22: 0 | AK22: 0 | AL22: no | AM22: clear | AN22: Non | AO22: Non | AP22: Non | AQ22: Non | AR22: Non | AS22: Non | AT22: 98.56 | AU22: DOSSIER_INCOMPLET | AV22: Dossier incomplet | AW22: 0 | AX22: Oui | AY22: 98.56 | AZ22: 100 | BA22: 100 | BB22: 100 | BC22: 94 | BD22: 100
A23: T19 | B23: Litige : alerte bloquante CTX | E23: SAIN | F23: 8 | G23: 85 | H23: claire | I23: 35 | J23: structure | K23: 100 | L23: definitives | M23: aligne | N23: standard | O23: 100 | P23: faible | Q23: faible | R23: 22 | S23: 100 | T23: 62 | U23: 100 | V23: 90 | W23: 1.35 | X23: 0 | Y23: 16 | Z23: 18 | AA23: 55 | AB23: 27 | AC23: 61 | AD23: 65 | AE23: 125 | AF23: oui | AG23: 3.2 | AH23: 5 | AI23: 0 | AJ23: 0 | AK23: 0 | AL23: no | AM23: litigation | AN23: Non | AO23: Non | AP23: Non | AQ23: Non | AR23: Non | AS23: Non | AT23: 98.56 | AU23: NO_GO | AV23: Souffrance | AW23: 0 | AX23: Non | AY23: 98.56 | AZ23: 100 | BA23: 100 | BB23: 100 | BC23: 94 | BD23: 100
A24: T20 | B24: Projet en difficulté (dégradé + non 1er rang) | C24: villas | D24: regions_interieures | E24: SENSIBLE | F24: 2 | G24: 120 | H24: partielle | I24: 50 | J24: regional | K24: 90 | L24: partielles | M24: moyen | N24: moyenne | O24: 90 | P24: moyen | Q24: moyenne | R24: 30 | S24: 70 | T24: 35 | U24: 90 | V24: 180 | W24: 0.95 | X24: 5 | Y24: 24 | Z24: 12 | AA24: 30 | AB24: 12 | AC24: 85 | AD24: 78 | AE24: 100 | AF24: non | AG24: 2 | AH24: -5 | AI24: 0 | AJ24: 0 | AK24: 0 | AL24: no | AM24: clear | AN24: Non | AO24: Non | AP24: Non | AQ24: Non | AR24: Non | AS24: Non | AT24: 0 | AU24: NO_GO | AV24: Sensible | AW24: 50 | AX24: Non | AY24: 51.5 | AZ24: 60 | BA24: 60 | BB24: 50 | BC24: 37.5 | BD24: 50

Sheet Historique
A1: Historique des calculs (journal)
A2: Alimenté par les macros (ScorerDossier, ScorerPortefeuille). La version du modèle est tracée sur chaque ligne.
A4: Date / heure | B4: Utilisateur | C4: Dossier | D4: Version du modèle | E4: Score final | F4: Décision | G4: Classe interne | H4: Malus D5 | I4: Dossier complet

Sheet P_General
A1: Paramètres généraux du modèle
A2: Cellules bleues = paramétrables. Toute modification doit être validée (macro ValiderModele) et versionnée.
A3: Paramètre | B3: Valeur
A4: Version du modèle | B4: v4.0.0
A5: Publié le | B5: 2026-09-28
A6: Échelle de notation des critères | B6: 10
A7: Seuil GO (score final ≥) | B7: 75
A8: Seuil GO sous conditions (≥) | B8: 65
A9: Seuil Watch list (≥) | B9: 50
A10: PD proxy — constante a | B10: 2.223
A11: PD proxy — coefficient b | B11: 0.0802
A12: Clé critique additionnelle | B12: dpd_days
A14: Domaines de notation
A15: Code | B15: Nom | C15: Poids
A16: D1 | B16: Sponsor & Gouvernance | C16: 0.25
A17: D2 | B17: Qualité intrinsèque du projet | C17: 0.2
A18: D3 | B18: Commercial & Cash-flow | C18: 0.31
A19: D4 | B19: Structuration financière & LGD | C19: 0.24
A25: Classes réglementaires (ordre de sévérité croissante)
A26: Code | B26: Libellé | C26: Défaut avéré | D26: Bloque GO | E26: Coefficient BAM
A27: SAIN | B27: Créance saine | C27: Non | D27: Non | E27: 1
A28: SENSIBLE | B28: Créance sensible (surveillance) | C28: Non | D28: Non | E28: 0.9
A29: PRE_DOUTEUX | B29: Pré-douteuse | C29: Oui | D29: Non | E29: 0.7
A30: DOUTEUX | B30: Douteuse | C30: Oui | D30: Non | E30: 0.4
A31: COMPROMIS | B31: Compromise | C31: Oui | D31: Non | E31: 0.2
A32: CTX | B32: Contentieux | C32: Oui | D32: Oui | E32: 0
A38: Grilles de pondération par phase (challenger — non adoptées)
A39: Phase | B39: D1 | C39: D2 | D39: D3 | E39: D4
A40: PRE_DEVELOPMENT | B40: 0.25 | C40: 0.3 | D40: 0.2 | E40: 0.25
A41: CONSTRUCTION | B41: 0.2 | C41: 0.25 | D41: 0.25 | E41: 0.3
A42: ECOULEMENT | B42: 0.15 | C42: 0.1 | D42: 0.35 | E42: 0.4
A44: Repères de retard de paiement (jours)
A45: Seuil pré-douteux | B45: 90
A46: Seuil douteux | B46: 180
A47: Seuil compromis | B47: 360

Sheet P_Criteres
A1: Critères de notation (29 dans la v4.0.0 — jusqu'à 60 lignes)
A2: Ajouter un critère = compléter une ligne + ses barèmes (P_Baremes) + sa clé dans Saisie. Poids du domaine : somme = 100 %.
A4: Code | B4: Domaine | C4: Libellé | D4: Type | E4: Poids | F4: Clé d'entrée | G4: Gate | H4: Seuil gate | I4: Jalon gate | J4: Famille | K4: Critique | L4: Unité
A5: D1C1 | B5: D1 | C5: Projets similaires livrés (5 ans) | D5: NUM | E5: 0.2 | F5: promoter_completed_projects | G5: Non | J5: ECONOMIC | K5: Non | L5: ratio/%
A6: D1C2 | B6: D1 | C6: Gearing promoteur (dettes nettes / FP) | D6: NUM | E6: 0.25 | F6: promoter_gearing | G6: Non | J6: ECONOMIC | K6: Non | L6: ratio/%
A7: D1C3 | B7: D1 | C7: Gouvernance & structure juridique | D7: QUAL | E7: 0.15 | F7: governance_quality | G7: Non | J7: ECONOMIC | K7: Non | L7: modalité
A8: D1C4 | B8: D1 | C8: Concentration mono-projet (CA projet / CA total) | D8: NUM | E8: 0.15 | F8: mono_project_concentration | G8: Non | J8: ECONOMIC | K8: Non | L8: ratio/%
A9: D1C5 | B9: D1 | C9: Typologie promoteur | D9: QUAL | E9: 0.1 | F9: promoter_type | G9: Non | J9: ECONOMIC | K9: Non | L9: modalité
A10: D1C6 | B10: D1 | C10: Apport effectif (injecté / prévu) | D10: NUM | E10: 0.15 | F10: equity_injected_ratio | G10: Oui | H10: 1 | I10: SIGNATURE | J10: ECONOMIC | K10: Non | L10: ratio/%
A11: D2C1 | B11: D2 | C11: Foncier & autorisations | D11: QUAL | E11: 0.1 | F11: land_permits_status | G11: Oui | H11: 1 | I11: TIRAGE | J11: ECONOMIC | K11: Non | L11: modalité
A12: D2C2 | B12: D2 | C12: Marché & positionnement | D12: QUAL | E12: 0.2 | F12: market_positioning | G12: Non | J12: ECONOMIC | K12: Non | L12: modalité
A13: D2C3 | B13: D2 | C13: Complexité technique | D13: QUAL | E13: 0.15 | F13: technical_complexity | G13: Non | J13: ECONOMIC | K13: Non | L13: modalité
A14: D2C4 | B14: D2 | C14: Avancement vs planning | D14: NUM | E14: 0.15 | F14: progress_vs_plan | G14: Non | J14: ECONOMIC | K14: Non | L14: ratio/%
A15: D2C5 | B15: D2 | C15: Litiges clients / SAV | D15: QUAL | E15: 0.1 | F15: sav_litigation | G15: Non | J15: ECONOMIC | K15: Non | L15: modalité
A16: D2C6 | B16: D2 | C16: Sensibilité macro / subvention | D16: QUAL | E16: 0.1 | F16: macro_sensitivity | G16: Non | J16: ECONOMIC | K16: Non | L16: modalité
A17: D2C7 | B17: D2 | C17: Coût foncier / CA | D17: NUM | E17: 0.1 | F17: land_cost_ratio | G17: Non | J17: ECONOMIC | K17: Non | L17: ratio/%
A18: D2C8 | B18: D2 | C18: Chaîne d'autorisations (complétude) | D18: NUM | E18: 0.1 | F18: authorization_completeness_pct | G18: Non | I18: TIRAGE | J18: ECONOMIC | K18: Non | L18: %
A19: D3C1 | B19: D3 | C19: Préventes sécurisées (encaissées / CA) | D19: NUM | E19: 0.15 | F19: pre_sale_rate | G19: Non | J19: ECONOMIC | K19: Oui | L19: ratio/%
A20: D3C2 | B20: D3 | C20: Ventes vs planning | D20: NUM | E20: 0.1 | F20: sales_vs_plan | G20: Non | J20: ECONOMIC | K20: Non | L20: ratio/%
A21: D3C3 | B21: D3 | C21: DSO (jours) | D21: NUM | E21: 0.1 | F21: dso_days | G21: Non | J21: ECONOMIC | K21: Non | L21: ratio/%
A22: D3C4 | B22: D3 | C22: Cash coverage (cash / échéances) | D22: NUM | E22: 0.2 | F22: cash_coverage | G22: Non | J22: ECONOMIC | K22: Oui | L22: ratio/%
A23: D3C5 | B23: D3 | C23: Impasse brute | D23: NUM | E23: 0.15 | F23: funding_gap_pct | G23: Non | J23: ECONOMIC | K23: Oui | L23: ratio/%
A24: D3C6 | B24: D3 | C24: Rotation stock (mois) | D24: NUM | E24: 0.1 | F24: stock_rotation_months | G24: Non | J24: ECONOMIC | K24: Non | L24: ratio/%
A25: D3C7 | B25: D3 | C25: Marge brute stressée (prix -10%) | D25: NUM | E25: 0.1 | F25: stressed_margin_pct | G25: Non | J25: ECONOMIC | K25: Non | L25: ratio/%
A26: D3C8 | B26: D3 | C26: Ventes sécurisées (financement acquéreur) | D26: NUM | E26: 0.1 | F26: secured_sales_rate | G26: Non | J26: ECONOMIC | K26: Non | L26: %
A27: D4C1 | B27: D4 | C27: Marge brute (CA - coûts directs)/CA | D27: NUM | E27: 0.2 | F27: gross_margin_pct | G27: Non | J27: ECONOMIC | K27: Oui | L27: ratio/%
A28: D4C2 | B28: D4 | C28: LTC (dette / coût total) | D28: NUM | E28: 0.15 | F28: ltc | G28: Non | J28: ECONOMIC | K28: Non | L28: ratio/%
A29: D4C3 | B29: D4 | C29: LTV stressée (dette / valeur×0,90) | D29: NUM | E29: 0.2 | F29: ltv_stressed | G29: Non | J29: GUARANTEE | K29: Non | L29: ratio/%
A30: D4C4 | B30: D4 | C30: Couverture garanties réalisable | D30: NUM | E30: 0.15 | F30: guarantee_coverage | G30: Non | J30: GUARANTEE | K30: Non | L30: ratio/%
... A33: D4C7 | B33: D4 | C33: Quotité de désengagement vs équilibre | D33: NUM | E33: 0.05 | F33: release_quotity_gap_pts | G33: Non | J33: GUARANTEE | K33: Non | L33: pts

Sheet P_Baremes
A1: Barèmes de notation
